Workbook

Sheet DESP_JANEIRO
A1: PREENCHER APENAS CÉLULAS COM FUNDO AZUL | D1: JANEIRO | E1: 2026 | F1: DIAS MÊS >>> | G1: =DAY(A256) -> 31 | I1: =IF(I256>$I258,"",WEEKDAY(I256)) -> 5 | J1: =IF(J256>$I258,"",WEEKDAY(J256)) -> 6 | K1: =IF(K256>$I258,"",WEEKDAY(K256)) -> 7 | L1: =IF(L256>$I258,"",WEEKDAY(L256)) -> 1 | M1: =IF(M256>$I258,"",WEEKDAY(M256)) -> 2 | N1: =IF(N256>$I258,"",WEEKDAY(N256)) -> 3 | O1: =IF(O256>$I258,"",WEEKDAY(O256)) -> 4 | P1: =IF(P256>$I258,"",WEEKDAY(P256)) -> 5 | ... AM1: =IF(AM256>$I258,"",WEEKDAY(AM256)) -> 7 | AN1: JUROS E MULTA | AQ1: O RESUMO MENSAL | AS1: O RESUMO MENSAL | AU1: O RESUMO MENSAL | AW1: O RESUMO MENSAL | AY1: O RESUMO MENSAL | BA1: O RESUMO MENSAL | BC1: O RESUMO MENSAL
A2: DESCRIÇÃO | B2: DESPESAS | D2: PAGAMENTOS | F2: HOJE >>>>>>> | G2: =DAY(TODAY()) -> 13 | I2: 1 | J2: =I2+1 -> 2 | K2: =J2+1 -> 3 | L2: =K2+1 -> 4 | M2: =L2+1 -> 5 | N2: =M2+1 -> 6 | O2: =N2+1 -> 7 | P2: =O2+1 -> 8 | Q2: =P2+1 -> 9 | ... AM2: =AL2+1 -> 31 | AN2: BOLETOS VENC. | AQ2: =+I2 -> 1 | AS2: =+J2 -> 2 | AU2: =+K2 -> 3 | AW2: =+L2 -> 4 | AY2: =+M2 -> 5 | BA2: =+N2 -> 6 | BC2: =+O2 -> 7
A3: PESSOAL | B3: A PAGAR | C3: DIA | D3: PAGO | E3: DIA | F3: ATRASO | G3: P/AP | AQ3: =+I1 -> 5 | AS3: =+J1 -> 6 | AU3: =+K1 -> 7 | AW3: =+L1 -> 1 | AY3: =+M1 -> 2 | BA3: =+N1 -> 3 | BC3: =+O1 -> 4
F4: e acumulado
A5: Sulamerica | B5: 6650 | C5: 2 | D5: 6650 | E5: 2 | F5: =+IF(TODAY()<DATEVALUE(1&D$1&E$1),0,IF(C5>0,IF(C5-SUM(I$255:AM$255)<0,B5-SUM(I5:AM5,0),0),0))+IF(C5=-1,B5-SUM(J5:AM5)) -> 0 | G5: =+IF(B5<1,"-",D5/B5) -> 1 | I5: =IF(I$2=$E5,$D5,IF(I$2>I$257,0,IF($C5=I$2,"PAGAR"&" "&TEXT($B5," #.##0,00"),IF($C5=-1,"PAGAR"&" "&TEXT($B5," #.##0,00"),0)))) -> 0 | J5: =+IF(J$2=$E5,$D5,IF(J$2>J$257,0,IF($C5=J$2,"PAGAR"&" "&TEXT($B5," #.##0,00"),0))) -> 6650 | K5: =+IF(K$2=$E5,$D5,IF(K$2>K$257,0,IF($C5=K$2,"PAGAR"&" "&TEXT($B5," #.##0,00"),0))) -> 0 | L5: =+IF(L$2=$E5,$D5,IF(L$2>L$257,0,IF($C5=L$2,"PAGAR"&" "&TEXT($B5," #.##0,00"),0))) -> 0 | M5: =+IF(M$2=$E5,$D5,IF(M$2>M$257,0,IF($C5=M$2,"PAGAR"&" "&TEXT($B5," #.##0,00"),0))) -> 0 | N5: =+IF(N$2=$E5,$D5,IF(N$2>N$257,0,IF($C5=N$2,"PAGAR"&" "&TEXT($B5," #.##0,00"),0))) -> 0 | O5: =+IF(O$2=$E5,$D5,IF(O$2>O$257,0,IF($C5=O$2,"PAGAR"&" "&TEXT($B5," #.##0,00"),0))) -> 0 | P5: =+IF(P$2=$E5,$D5,IF(P$2>P$257,0,IF($C5=P$2,"PAGAR"&" "&TEXT($B5," #.##0,00"),0))) -> 0 | Q5: =+IF(Q$2=$E5,$D5,IF(Q$2>Q$257,0,IF($C5=Q$2,"PAGAR"&" "&TEXT($B5," #.##0,00"),0))) -> 0 | ... AM5: =+IF(AM$2=$E5,$D5,IF(AM$2>AM$257,0,IF($C5=AM$2,"PAGAR"&" "&TEXT($B5," #.##0,00"),0))) -> 0 | AN5: =+IF(F5<0,-F5,0) -> 0 | AO5: =+IF(AND(C5=0,B5>0),B5,0) -> 0 | AQ5: {=_xlfn._xlws.FILTER($A$5:$A$152,$C$5:$C$152=AQ2,"livre")} -> Condomínio Sta Rita | AR5: {=_xlfn._xlws.FILTER($B$5:$B$152,$C$5:$C$152=AQ2,"livre")} -> 300 | AS5: {=_xlfn._xlws.FILTER($A$5:$A$152,$C$5:$C$152=AS2,"livre")} -> Sulamerica | AT5: {=_xlfn._xlws.FILTER($B$5:$B$152,$C$5:$C$152=AS2,"livre")} -> 6650 | AU5: {=_xlfn._xlws.FILTER($A$5:$A$152,$C$5:$C$152=AU2,"livre")} -> Apple - Cartão | AV5: {=_xlfn._xlws.FILTER($B$5:$B$152,$C$5:$C$152=AU2,"livre")} -> 5.9 | AW5: {=_xlfn._xlws.FILTER($A$5:$A$152,$C$5:$C$152=AW2,"livre")} -> Google Adobe - Cartão | AX5: {=_xlfn._xlws.FILTER($B$5:$B$152,$C$5:$C$152=AW2,"livre")} -> 22.99 | AY5: {=_xlfn._xlws.FILTER($A$5:$A$152,$C$5:$C$152=AY2,"livre")} -> Apple.com - Cartão | AZ5: {=_xlfn._xlws.FILTER($B$5:$B$152,$C$5:$C$152=AY2,"livre")} -> 5.9 | BA5: {=_xlfn._xlws.FILTER($A$5:$A$152,$C$5:$C$152=BA2,"livre")} -> Francisca | BB5: {=_xlfn._xlws.FILTER($B$5:$B$152,$C$5:$C$152=BA2,"livre")} -> 1080 | BC5: {=_xlfn._xlws.FILTER($A$5:$A$152,$C$5:$C$152=BC2,"livre")} -> Sulamerica | BD5: {=_xlfn._xlws.FILTER($B$5:$B$152,$C$5:$C$152=BC2,"livre")} -> 6359.51
A6: Sulamerica | B6: 6359.51 | C6: 7 | F6: =+IF(TODAY()<DATEVALUE(1&D$1&E$1),0,IF(C6>0,IF(C6-SUM(I$255:AM$255)<0,B6-SUM(I6:AM6,0),0),0))+IF(C6=-1,B6-SUM(J6:AM6)) -> 6359.51 | G6: =+IF(B6<1,"-",D6/B6) -> 0 | I6: =IF(I$2=$E6,$D6,IF(I$2>I$257,0,IF($C6=I$2,"PAGAR"&" "&TEXT($B6," #.##0,00"),IF($C6=-1,"PAGAR"&" "&TEXT($B6," #.##0,00"),0)))) -> 0 | J6: =+IF(J$2=$E6,$D6,IF(J$2>J$257,0,IF($C6=J$2,"PAGAR"&" "&TEXT($B6," #.##0,00"),0))) -> 0 | K6: =+IF(K$2=$E6,$D6,IF(K$2>K$257,0,IF($C6=K$2,"PAGAR"&" "&TEXT($B6," #.##0,00"),0))) -> 0 | L6: =+IF(L$2=$E6,$D6,IF(L$2>L$257,0,IF($C6=L$2,"PAGAR"&" "&TEXT($B6," #.##0,00"),0))) -> 0 | M6: =+IF(M$2=$E6,$D6,IF(M$2>M$257,0,IF($C6=M$2,"PAGAR"&" "&TEXT($B6," #.##0,00"),0))) -> 0 | N6: =+IF(N$2=$E6,$D6,IF(N$2>N$257,0,IF($C6=N$2,"PAGAR"&" "&TEXT($B6," #.##0,00"),0))) -> 0 | O6: =+IF(O$2=$E6,$D6,IF(O$2>O$257,0,IF($C6=O$2,"PAGAR"&" "&TEXT($B6," #.##0,00"),0))) -> PAGAR 6.359,51 | P6: =+IF(P$2=$E6,$D6,IF(P$2>P$257,0,IF($C6=P$2,"PAGAR"&" "&TEXT($B6," #.##0,00"),0))) -> 0 | Q6: =+IF(Q$2=$E6,$D6,IF(Q$2>Q$257,0,IF($C6=Q$2,"PAGAR"&" "&TEXT($B6," #.##0,00"),0))) -> 0 | ... AM6: =+IF(AM$2=$E6,$D6,IF(AM$2>AM$257,0,IF($C6=AM$2,"PAGAR"&" "&TEXT($B6," #.##0,00"),0))) -> 0 | AN6: =+IF(F6<0,-F6,0) -> 0 | AO6: =+IF(AND(C6=0,B6>0),B6,0) -> 0 | AQ6: Letízio mensal | AR6: 1750 | AS6: Clayton manutenção | AT6: 1000 | AU6: Microsoft Office - Cartão | AV6: 60 | AY6: Claro Reserva | AZ6: 288.06 | BA6: CPFL Ágata | BB6: 173.49 | BC6: Netflix - cartão | BD6: 44.9
A7: Seguro Vida Presente 16 | B7: 770.07 | C7: 0 | D7: 770.07 | E7: 12 | F7: =+IF(TODAY()<DATEVALUE(1&D$1&E$1),0,IF(C7>0,IF(C7-SUM(I$255:AM$255)<0,B7-SUM(I7:AM7,0),0),0))+IF(C7=-1,B7-SUM(J7:AM7)) -> 0 | G7: =+IF(B7<1,"-",D7/B7) -> 1 | I7: =IF(I$2=$E7,$D7,IF(I$2>I$257,0,IF($C7=I$2,"PAGAR"&" "&TEXT($B7," #.##0,00"),IF($C7=-1,"PAGAR"&" "&TEXT($B7," #.##0,00"),0)))) -> 0 | J7: =+IF(J$2=$E7,$D7,IF(J$2>J$257,0,IF($C7=J$2,"PAGAR"&" "&TEXT($B7," #.##0,00"),0))) -> 0 | K7: =+IF(K$2=$E7,$D7,IF(K$2>K$257,0,IF($C7=K$2,"PAGAR"&" "&TEXT($B7," #.##0,00"),0))) -> 0 | L7: =+IF(L$2=$E7,$D7,IF(L$2>L$257,0,IF($C7=L$2,"PAGAR"&" "&TEXT($B7," #.##0,00"),0))) -> 0 | M7: =+IF(M$2=$E7,$D7,IF(M$2>M$257,0,IF($C7=M$2,"PAGAR"&" "&TEXT($B7," #.##0,00"),0))) -> 0 | N7: =+IF(N$2=$E7,$D7,IF(N$2>N$257,0,IF($C7=N$2,"PAGAR"&" "&TEXT($B7," #.##0,00"),0))) -> 0 | O7: =+IF(O$2=$E7,$D7,IF(O$2>O$257,0,IF($C7=O$2,"PAGAR"&" "&TEXT($B7," #.##0,00"),0))) -> 0 | P7: =+IF(P$2=$E7,$D7,IF(P$2>P$257,0,IF($C7=P$2,"PAGAR"&" "&TEXT($B7," #.##0,00"),0))) -> 0 | Q7: =+IF(Q$2=$E7,$D7,IF(Q$2>Q$257,0,IF($C7=Q$2,"PAGAR"&" "&TEXT($B7," #.##0,00"),0))) -> 0 | ... AM7: =+IF(AM$2=$E7,$D7,IF(AM$2>AM$257,0,IF($C7=AM$2,"PAGAR"&" "&TEXT($B7," #.##0,00"),0))) -> 0 | AN7: =+IF(F7<0,-F7,0) -> 0 | AO7: =+IF(AND(C7=0,B7>0),B7,0) -> 770.07 | AS7: VT | AT7: 500 | AU7: VA 5 anos | AV7: 1890 | AY7: Itaú - pron. débito auto (6/24x) 1,6% 150k | AZ7: 5188 | BA7: AGDES Reserva | BB7: 291.1
A8: Seguro Vida Presente 21 | B8: 770.07 | C8: 25 | D8: 770.07 | E8: 10 | F8: =+IF(TODAY()<DATEVALUE(1&D$1&E$1),0,IF(C8>0,IF(C8-SUM(I$255:AM$255)<0,B8-SUM(I8:AM8,0),0),0))+IF(C8=-1,B8-SUM(J8:AM8)) -> 0 | G8: =+IF(B8<1,"-",D8/B8) -> 1 | I8: =IF(I$2=$E8,$D8,IF(I$2>I$257,0,IF($C8=I$2,"PAGAR"&" "&TEXT($B8," #.##0,00"),IF($C8=-1,"PAGAR"&" "&TEXT($B8," #.##0,00"),0)))) -> 0 | J8: =+IF(J$2=$E8,$D8,IF(J$2>J$257,0,IF($C8=J$2,"PAGAR"&" "&TEXT($B8," #.##0,00"),0))) -> 0 | K8: =+IF(K$2=$E8,$D8,IF(K$2>K$257,0,IF($C8=K$2,"PAGAR"&" "&TEXT($B8," #.##0,00"),0))) -> 0 | L8: =+IF(L$2=$E8,$D8,IF(L$2>L$257,0,IF($C8=L$2,"PAGAR"&" "&TEXT($B8," #.##0,00"),0))) -> 0 | M8: =+IF(M$2=$E8,$D8,IF(M$2>M$257,0,IF($C8=M$2,"PAGAR"&" "&TEXT($B8," #.##0,00"),0))) -> 0 | N8: =+IF(N$2=$E8,$D8,IF(N$2>N$257,0,IF($C8=N$2,"PAGAR"&" "&TEXT($B8," #.##0,00"),0))) -> 0 | O8: =+IF(O$2=$E8,$D8,IF(O$2>O$257,0,IF($C8=O$2,"PAGAR"&" "&TEXT($B8," #.##0,00"),0))) -> 0 | P8: =+IF(P$2=$E8,$D8,IF(P$2>P$257,0,IF($C8=P$2,"PAGAR"&" "&TEXT($B8," #.##0,00"),0))) -> 0 | Q8: =+IF(Q$2=$E8,$D8,IF(Q$2>Q$257,0,IF($C8=Q$2,"PAGAR"&" "&TEXT($B8," #.##0,00"),0))) -> 0 | ... AM8: =+IF(AM$2=$E8,$D8,IF(AM$2>AM$257,0,IF($C8=AM$2,"PAGAR"&" "&TEXT($B8," #.##0,00"),0))) -> 0 | AN8: =+IF(F8<0,-F8,0) -> 0 | AO8: =+IF(AND(C8=0,B8>0),B8,0) -> 0 | AU8: Lucas VA 5 anos e normal | AV8: 420 | AY8: Frees + R$400 Josiane | AZ8: 6900 | BA8: 4 Lock -- folha | BB8: 12000
A9: Seguro Previdência VGBL 21 | B9: 675.52 | C9: 25 | F9: =+IF(TODAY()<DATEVALUE(1&D$1&E$1),0,IF(C9>0,IF(C9-SUM(I$255:AM$255)<0,B9-SUM(I9:AM9,0),0),0))+IF(C9=-1,B9-SUM(J9:AM9)) -> 0 | G9: =+IF(B9=0,"-",D9/B9) -> 0 | I9: =IF(I$2=$E9,$D9,IF(I$2>I$257,0,IF($C9=I$2,"PAGAR"&" "&TEXT($B9," #.##0,00"),IF($C9=-1,"PAGAR"&" "&TEXT($B9," #.##0,00"),0)))) -> 0 | J9: =+IF(J$2=$E9,$D9,IF(J$2>J$257,0,IF($C9=J$2,"PAGAR"&" "&TEXT($B9," #.##0,00"),0))) -> 0 | K9: =+IF(K$2=$E9,$D9,IF(K$2>K$257,0,IF($C9=K$2,"PAGAR"&" "&TEXT($B9," #.##0,00"),0))) -> 0 | L9: =+IF(L$2=$E9,$D9,IF(L$2>L$257,0,IF($C9=L$2,"PAGAR"&" "&TEXT($B9," #.##0,00"),0))) -> 0 | M9: =+IF(M$2=$E9,$D9,IF(M$2>M$257,0,IF($C9=M$2,"PAGAR"&" "&TEXT($B9," #.##0,00"),0))) -> 0 | N9: =+IF(N$2=$E9,$D9,IF(N$2>N$257,0,IF($C9=N$2,"PAGAR"&" "&TEXT($B9," #.##0,00"),0))) -> 0 | O9: =+IF(O$2=$E9,$D9,IF(O$2>O$257,0,IF($C9=O$2,"PAGAR"&" "&TEXT($B9," #.##0,00"),0))) -> 0 | P9: =+IF(P$2=$E9,$D9,IF(P$2>P$257,0,IF($C9=P$2,"PAGAR"&" "&TEXT($B9," #.##0,00"),0))) -> 0 | Q9: =+IF(Q$2=$E9,$D9,IF(Q$2>Q$257,0,IF($C9=Q$2,"PAGAR"&" "&TEXT($B9," #.##0,00"),0))) -> 0 | ... AM9: =+IF(AM$2=$E9,$D9,IF(AM$2>AM$257,0,IF($C9=AM$2,"PAGAR"&" "&TEXT($B9," #.##0,00"),0))) -> 0 | AN9: =+IF(F9<0,-F9,0) -> 0 | AO9: =+IF(AND(C9=0,B9>0),B9,0) -> 0 | BA9: Perfecto -- folha | BB9: 1500
A10: Cartão | B10: 1928.17 | C10: 28 | F10: =+IF(TODAY()<DATEVALUE(1&D$1&E$1),0,IF(C10>0,IF(C10-SUM(I$255:AM$255)<0,B10-SUM(I10:AM10,0),0),0))+IF(C10=-1,B10-SUM(J10:AM10)) -> 0 | G10: =+IF(B10=0,"-",D10/B10) -> 0 | I10: =IF(I$2=$E10,$D10,IF(I$2>I$257,0,IF($C10=I$2,"PAGAR"&" "&TEXT($B10," #.##0,00"),IF($C10=-1,"PAGAR"&" "&TEXT($B10," #.##0,00"),0)))) -> 0 | J10: =+IF(J$2=$E10,$D10,IF(J$2>J$257,0,IF($C10=J$2,"PAGAR"&" "&TEXT($B10," #.##0,00"),0))) -> 0 | K10: =+IF(K$2=$E10,$D10,IF(K$2>K$257,0,IF($C10=K$2,"PAGAR"&" "&TEXT($B10," #.##0,00"),0))) -> 0 | L10: =+IF(L$2=$E10,$D10,IF(L$2>L$257,0,IF($C10=L$2,"PAGAR"&" "&TEXT($B10," #.##0,00"),0))) -> 0 | M10: =+IF(M$2=$E10,$D10,IF(M$2>M$257,0,IF($C10=M$2,"PAGAR"&" "&TEXT($B10," #.##0,00"),0))) -> 0 | N10: =+IF(N$2=$E10,$D10,IF(N$2>N$257,0,IF($C10=N$2,"PAGAR"&" "&TEXT($B10," #.##0,00"),0))) -> 0 | O10: =+IF(O$2=$E10,$D10,IF(O$2>O$257,0,IF($C10=O$2,"PAGAR"&" "&TEXT($B10," #.##0,00"),0))) -> 0 | P10: =+IF(P$2=$E10,$D10,IF(P$2>P$257,0,IF($C10=P$2,"PAGAR"&" "&TEXT($B10," #.##0,00"),0))) -> 0 | Q10: =+IF(Q$2=$E10,$D10,IF(Q$2>Q$257,0,IF($C10=Q$2,"PAGAR"&" "&TEXT($B10," #.##0,00"),0))) -> 0 | ... AM10: =+IF(AM$2=$E10,$D10,IF(AM$2>AM$257,0,IF($C10=AM$2,"PAGAR"&" "&TEXT($B10," #.##0,00"),0))) -> 0 | AN10: =+IF(F10<0,-F10,0) -> 0 | AO10: =+IF(AND(C10=0,B10>0),B10,0) -> 0
A11: Apple - Cartão | B11: 5.9 | C11: 3 | F11: =+IF(TODAY()<DATEVALUE(1&D$1&E$1),0,IF(C11>0,IF(C11-SUM(I$255:AM$255)<0,B11-SUM(I11:AM11,0),0),0))+IF(C11=-1,B11-SUM(J11:AM11)) -> 5.9 | G11: =+IF(B11=0,"-",D11/B11) -> 0 | I11: =IF(I$2=$E11,$D11,IF(I$2>I$257,0,IF($C11=I$2,"PAGAR"&" "&TEXT($B11," #.##0,00"),IF($C11=-1,"PAGAR"&" "&TEXT($B11," #.##0,00"),0)))) -> 0 | J11: =+IF(J$2=$E11,$D11,IF(J$2>J$257,0,IF($C11=J$2,"PAGAR"&" "&TEXT($B11," #.##0,00"),0))) -> 0 | K11: =+IF(K$2=$E11,$D11,IF(K$2>K$257,0,IF($C11=K$2,"PAGAR"&" "&TEXT($B11," #.##0,00"),0))) -> PAGAR 5,90 | L11: =+IF(L$2=$E11,$D11,IF(L$2>L$257,0,IF($C11=L$2,"PAGAR"&" "&TEXT($B11," #.##0,00"),0))) -> 0 | M11: =+IF(M$2=$E11,$D11,IF(M$2>M$257,0,IF($C11=M$2,"PAGAR"&" "&TEXT($B11," #.##0,00"),0))) -> 0 | N11: =+IF(N$2=$E11,$D11,IF(N$2>N$257,0,IF($C11=N$2,"PAGAR"&" "&TEXT($B11," #.##0,00"),0))) -> 0 | O11: =+IF(O$2=$E11,$D11,IF(O$2>O$257,0,IF($C11=O$2,"PAGAR"&" "&TEXT($B11," #.##0,00"),0))) -> 0 | P11: =+IF(P$2=$E11,$D11,IF(P$2>P$257,0,IF($C11=P$2,"PAGAR"&" "&TEXT($B11," #.##0,00"),0))) -> 0 | Q11: =+IF(Q$2=$E11,$D11,IF(Q$2>Q$257,0,IF($C11=Q$2,"PAGAR"&" "&TEXT($B11," #.##0,00"),0))) -> 0 | ... AM11: =+IF(AM$2=$E11,$D11,IF(AM$2>AM$257,0,IF($C11=AM$2,"PAGAR"&" "&TEXT($B11," #.##0,00"),0))) -> 0 | AN11: =+IF(F11<0,-F11,0) -> 0 | AO11: =+IF(AND(C11=0,B11>0),B11,0) -> 0
A12: Netflix - cartão | B12: 44.9 | C12: 7 | F12: =+IF(TODAY()<DATEVALUE(1&D$1&E$1),0,IF(C12>0,IF(C12-SUM(I$255:AM$255)<0,B12-SUM(I12:AM12,0),0),0))+IF(C12=-1,B12-SUM(J12:AM12)) -> 44.9 | G12: =+IF(B12=0,"-",D12/B12) -> 0 | I12: =IF(I$2=$E12,$D12,IF(I$2>I$257,0,IF($C12=I$2,"PAGAR"&" "&TEXT($B12," #.##0,00"),IF($C12=-1,"PAGAR"&" "&TEXT($B12," #.##0,00"),0)))) -> 0 | J12: =+IF(J$2=$E12,$D12,IF(J$2>J$257,0,IF($C12=J$2,"PAGAR"&" "&TEXT($B12," #.##0,00"),0))) -> 0 | K12: =+IF(K$2=$E12,$D12,IF(K$2>K$257,0,IF($C12=K$2,"PAGAR"&" "&TEXT($B12," #.##0,00"),0))) -> 0 | L12: =+IF(L$2=$E12,$D12,IF(L$2>L$257,0,IF($C12=L$2,"PAGAR"&" "&TEXT($B12," #.##0,00"),0))) -> 0 | M12: =+IF(M$2=$E12,$D12,IF(M$2>M$257,0,IF($C12=M$2,"PAGAR"&" "&TEXT($B12," #.##0,00"),0))) -> 0 | N12: =+IF(N$2=$E12,$D12,IF(N$2>N$257,0,IF($C12=N$2,"PAGAR"&" "&TEXT($B12," #.##0,00"),0))) -> 0 | O12: =+IF(O$2=$E12,$D12,IF(O$2>O$257,0,IF($C12=O$2,"PAGAR"&" "&TEXT($B12," #.##0,00"),0))) -> PAGAR 44,90 | P12: =+IF(P$2=$E12,$D12,IF(P$2>P$257,0,IF($C12=P$2,"PAGAR"&" "&TEXT($B12," #.##0,00"),0))) -> 0 | Q12: =+IF(Q$2=$E12,$D12,IF(Q$2>Q$257,0,IF($C12=Q$2,"PAGAR"&" "&TEXT($B12," #.##0,00"),0))) -> 0 | ... AM12: =+IF(AM$2=$E12,$D12,IF(AM$2>AM$257,0,IF($C12=AM$2,"PAGAR"&" "&TEXT($B12," #.##0,00"),0))) -> 0 | AN12: =+IF(F12<0,-F12,0) -> 0 | AO12: =+IF(AND(C12=0,B12>0),B12,0) -> 0
A13: Google One IA - Cartão | B13: 96.99 | C13: 22 | F13: =+IF(TODAY()<DATEVALUE(1&D$1&E$1),0,IF(C13>0,IF(C13-SUM(I$255:AM$255)<0,B13-SUM(I13:AM13,0),0),0))+IF(C13=-1,B13-SUM(J13:AM13)) -> 0 | G13: =+IF(B13=0,"-",D13/B13) -> 0 | I13: =IF(I$2=$E13,$D13,IF(I$2>I$257,0,IF($C13=I$2,"PAGAR"&" "&TEXT($B13," #.##0,00"),IF($C13=-1,"PAGAR"&" "&TEXT($B13," #.##0,00"),0)))) -> 0 | J13: =+IF(J$2=$E13,$D13,IF(J$2>J$257,0,IF($C13=J$2,"PAGAR"&" "&TEXT($B13," #.##0,00"),0))) -> 0 | K13: =+IF(K$2=$E13,$D13,IF(K$2>K$257,0,IF($C13=K$2,"PAGAR"&" "&TEXT($B13," #.##0,00"),0))) -> 0 | L13: =+IF(L$2=$E13,$D13,IF(L$2>L$257,0,IF($C13=L$2,"PAGAR"&" "&TEXT($B13," #.##0,00"),0))) -> 0 | M13: =+IF(M$2=$E13,$D13,IF(M$2>M$257,0,IF($C13=M$2,"PAGAR"&" "&TEXT($B13," #.##0,00"),0))) -> 0 | N13: =+IF(N$2=$E13,$D13,IF(N$2>N$257,0,IF($C13=N$2,"PAGAR"&" "&TEXT($B13," #.##0,00"),0))) -> 0 | O13: =+IF(O$2=$E13,$D13,IF(O$2>O$257,0,IF($C13=O$2,"PAGAR"&" "&TEXT($B13," #.##0,00"),0))) -> 0 | P13: =+IF(P$2=$E13,$D13,IF(P$2>P$257,0,IF($C13=P$2,"PAGAR"&" "&TEXT($B13," #.##0,00"),0))) -> 0 | Q13: =+IF(Q$2=$E13,$D13,IF(Q$2>Q$257,0,IF($C13=Q$2,"PAGAR"&" "&TEXT($B13," #.##0,00"),0))) -> 0 | ... AM13: =+IF(AM$2=$E13,$D13,IF(AM$2>AM$257,0,IF($C13=AM$2,"PAGAR"&" "&TEXT($B13," #.##0,00"),0))) -> 0 | AN13: =+IF(F13<0,-F13,0) -> 0 | AO13: =+IF(AND(C13=0,B13>0),B13,0) -> 0
A14: Yelum Seguro Civic - Cartão | B14: 286.78 | C14: 28 | F14: =+IF(TODAY()<DATEVALUE(1&D$1&E$1),0,IF(C14>0,IF(C14-SUM(I$255:AM$255)<0,B14-SUM(I14:AM14,0),0),0))+IF(C14=-1,B14-SUM(J14:AM14)) -> 0 | G14: =+IF(B14=0,"-",D14/B14) -> 0 | I14: =IF(I$2=$E14,$D14,IF(I$2>I$257,0,IF($C14=I$2,"PAGAR"&" "&TEXT($B14," #.##0,00"),IF($C14=-1,"PAGAR"&" "&TEXT($B14," #.##0,00"),0)))) -> 0 | J14: =+IF(J$2=$E14,$D14,IF(J$2>J$257,0,IF($C14=J$2,"PAGAR"&" "&TEXT($B14," #.##0,00"),0))) -> 0 | K14: =+IF(K$2=$E14,$D14,IF(K$2>K$257,0,IF($C14=K$2,"PAGAR"&" "&TEXT($B14," #.##0,00"),0))) -> 0 | L14: =+IF(L$2=$E14,$D14,IF(L$2>L$257,0,IF($C14=L$2,"PAGAR"&" "&TEXT($B14," #.##0,00"),0))) -> 0 | M14: =+IF(M$2=$E14,$D14,IF(M$2>M$257,0,IF($C14=M$2,"PAGAR"&" "&TEXT($B14," #.##0,00"),0))) -> 0 | N14: =+IF(N$2=$E14,$D14,IF(N$2>N$257,0,IF($C14=N$2,"PAGAR"&" "&TEXT($B14," #.##0,00"),0))) -> 0 | O14: =+IF(O$2=$E14,$D14,IF(O$2>O$257,0,IF($C14=O$2,"PAGAR"&" "&TEXT($B14," #.##0,00"),0))) -> 0 | P14: =+IF(P$2=$E14,$D14,IF(P$2>P$257,0,IF($C14=P$2,"PAGAR"&" "&TEXT($B14," #.##0,00"),0))) -> 0 | Q14: =+IF(Q$2=$E14,$D14,IF(Q$2>Q$257,0,IF($C14=Q$2,"PAGAR"&" "&TEXT($B14," #.##0,00"),0))) -> 0 | ... AM14: =+IF(AM$2=$E14,$D14,IF(AM$2>AM$257,0,IF($C14=AM$2,"PAGAR"&" "&TEXT($B14," #.##0,00"),0))) -> 0 | AN14: =+IF(F14<0,-F14,0) -> 0 | AO14: =+IF(AND(C14=0,B14>0),B14,0) -> 0
A15: Apple.com - Cartão | B15: 29.9 | C15: 28 | F15: =+IF(TODAY()<DATEVALUE(1&D$1&E$1),0,IF(C15>0,IF(C15-SUM(I$255:AM$255)<0,B15-SUM(I15:AM15,0),0),0))+IF(C15=-1,B15-SUM(J15:AM15)) -> 0 | G15: =+IF(B15=0,"-",D15/B15) -> 0 | I15: =IF(I$2=$E15,$D15,IF(I$2>I$257,0,IF($C15=I$2,"PAGAR"&" "&TEXT($B15," #.##0,00"),IF($C15=-1,"PAGAR"&" "&TEXT($B15," #.##0,00"),0)))) -> 0 | J15: =+IF(J$2=$E15,$D15,IF(J$2>J$257,0,IF($C15=J$2,"PAGAR"&" "&TEXT($B15," #.##0,00"),0))) -> 0 | K15: =+IF(K$2=$E15,$D15,IF(K$2>K$257,0,IF($C15=K$2,"PAGAR"&" "&TEXT($B15," #.##0,00"),0))) -> 0 | L15: =+IF(L$2=$E15,$D15,IF(L$2>L$257,0,IF($C15=L$2,"PAGAR"&" "&TEXT($B15," #.##0,00"),0))) -> 0 | M15: =+IF(M$2=$E15,$D15,IF(M$2>M$257,0,IF($C15=M$2,"PAGAR"&" "&TEXT($B15," #.##0,00"),0))) -> 0 | N15: =+IF(N$2=$E15,$D15,IF(N$2>N$257,0,IF($C15=N$2,"PAGAR"&" "&TEXT($B15," #.##0,00"),0))) -> 0 | O15: =+IF(O$2=$E15,$D15,IF(O$2>O$257,0,IF($C15=O$2,"PAGAR"&" "&TEXT($B15," #.##0,00"),0))) -> 0 | P15: =+IF(P$2=$E15,$D15,IF(P$2>P$257,0,IF($C15=P$2,"PAGAR"&" "&TEXT($B15," #.##0,00"),0))) -> 0 | Q15: =+IF(Q$2=$E15,$D15,IF(Q$2>Q$257,0,IF($C15=Q$2,"PAGAR"&" "&TEXT($B15," #.##0,00"),0))) -> 0 | ... AM15: =+IF(AM$2=$E15,$D15,IF(AM$2>AM$257,0,IF($C15=AM$2,"PAGAR"&" "&TEXT($B15," #.##0,00"),0))) -> 0 | AN15: =+IF(F15<0,-F15,0) -> 0 | AO15: =+IF(AND(C15=0,B15>0),B15,0) -> 0 | AQ15: =+P2 -> 8 | AS15: =+Q2 -> 9 | AU15: =+R2 -> 10 | AW15: =+S2 -> 11 | AY15: =+T2 -> 12 | BA15: =+U2 -> 13 | BC15: =+V2 -> 14
A16: Apple.com - Cartão | B16: 5.9 | C16: 5 | F16: =+IF(TODAY()<DATEVALUE(1&D$1&E$1),0,IF(C16>0,IF(C16-SUM(I$255:AM$255)<0,B16-SUM(I16:AM16,0),0),0))+IF(C16=-1,B16-SUM(J16:AM16)) -> 5.9 | G16: =+IF(B16=0,"-",D16/B16) -> 0 | I16: =IF(I$2=$E16,$D16,IF(I$2>I$257,0,IF($C16=I$2,"PAGAR"&" "&TEXT($B16," #.##0,00"),IF($C16=-1,"PAGAR"&" "&TEXT($B16," #.##0,00"),0)))) -> 0 | J16: =+IF(J$2=$E16,$D16,IF(J$2>J$257,0,IF($C16=J$2,"PAGAR"&" "&TEXT($B16," #.##0,00"),0))) -> 0 | K16: =+IF(K$2=$E16,$D16,IF(K$2>K$257,0,IF($C16=K$2,"PAGAR"&" "&TEXT($B16," #.##0,00"),0))) -> 0 | L16: =+IF(L$2=$E16,$D16,IF(L$2>L$257,0,IF($C16=L$2,"PAGAR"&" "&TEXT($B16," #.##0,00"),0))) -> 0 | M16: =+IF(M$2=$E16,$D16,IF(M$2>M$257,0,IF($C16=M$2,"PAGAR"&" "&TEXT($B16," #.##0,00"),0))) -> PAGAR 5,90 | N16: =+IF(N$2=$E16,$D16,IF(N$2>N$257,0,IF($C16=N$2,"PAGAR"&" "&TEXT($B16," #.##0,00"),0))) -> 0 | O16: =+IF(O$2=$E16,$D16,IF(O$2>O$257,0,IF($C16=O$2,"PAGAR"&" "&TEXT($B16," #.##0,00"),0))) -> 0 | P16: =+IF(P$2=$E16,$D16,IF(P$2>P$257,0,IF($C16=P$2,"PAGAR"&" "&TEXT($B16," #.##0,00"),0))) -> 0 | Q16: =+IF(Q$2=$E16,$D16,IF(Q$2>Q$257,0,IF($C16=Q$2,"PAGAR"&" "&TEXT($B16," #.##0,00"),0))) -> 0 | ... AM16: =+IF(AM$2=$E16,$D16,IF(AM$2>AM$257,0,IF($C16=AM$2,"PAGAR"&" "&TEXT($B16," #.##0,00"),0))) -> 0 | AN16: =+IF(F16<0,-F16,0) -> 0 | AO16: =+IF(AND(C16=0,B16>0),B16,0) -> 0 | AQ16: {=_xlfn._xlws.FILTER($A5:$A152,$C5:$C152=AQ15,"livre")} -> 5asec (22/22 parcelas) | AR16: {=_xlfn._xlws.FILTER($B5:$B152,$C5:$C152=AQ15,"livre")} -> 10606.05 | AS16: {=_xlfn._xlws.FILTER($A5:$A152,$C5:$C152=AS15,"livre")} -> ACGDES Barão | AT16: {=_xlfn._xlws.FILTER($B5:$B152,$C5:$C152=AS15,"livre")} -> 931.52 | AU16: {=_xlfn._xlws.FILTER($A5:$A152,$C5:$C152=AU15,"livre")} -> Condomínio Reserva (Nelson58@) | AV16: {=_xlfn._xlws.FILTER($B5:$B152,$C5:$C152=AU15,"livre")} -> 1504.62 | AW16: {=_xlfn._xlws.FILTER($A5:$A152,$C5:$C152=AW15,"livre")} -> Escritório Aluguel | AX16: {=_xlfn._xlws.FILTER($B5:$B152,$C5:$C152=AW15,"livre")} -> 2945.42 | AY16: {=_xlfn._xlws.FILTER($A5:$A152,$C5:$C152=AY15,"livre")} -> CPFL Reserva | AZ16: {=_xlfn._xlws.FILTER($B5:$B152,$C5:$C152=AY15,"livre")} -> 159.64 | BA16: {=_xlfn._xlws.FILTER($A5:$A152,$C5:$C152=BA15,"livre")} -> ACGDES Sunset | BB16: {=_xlfn._xlws.FILTER($B5:$B152,$C5:$C152=BA15,"livre")} -> 2221.74 | BC16: {=_xlfn._xlws.FILTER($A5:$A152,$C5:$C152=BC15,"livre")} -> livre | BD16: {=_xlfn._xlws.FILTER($B5:$B152,$C5:$C152=BC15,"livre")} -> livre
A17: Google Adobe - Cartão | B17: 22.99 | C17: 4 | F17: =+IF(TODAY()<DATEVALUE(1&D$1&E$1),0,IF(C17>0,IF(C17-SUM(I$255:AM$255)<0,B17-SUM(I17:AM17,0),0),0))+IF(C17=-1,B17-SUM(J17:AM17)) -> 22.99 | G17: =+IF(B17=0,"-",D17/B17) -> 0 | I17: =IF(I$2=$E17,$D17,IF(I$2>I$257,0,IF($C17=I$2,"PAGAR"&" "&TEXT($B17," #.##0,00"),IF($C17=-1,"PAGAR"&" "&TEXT($B17," #.##0,00"),0)))) -> 0 | J17: =+IF(J$2=$E17,$D17,IF(J$2>J$257,0,IF($C17=J$2,"PAGAR"&" "&TEXT($B17," #.##0,00"),0))) -> 0 | K17: =+IF(K$2=$E17,$D17,IF(K$2>K$257,0,IF($C17=K$2,"PAGAR"&" "&TEXT($B17," #.##0,00"),0))) -> 0 | L17: =+IF(L$2=$E17,$D17,IF(L$2>L$257,0,IF($C17=L$2,"PAGAR"&" "&TEXT($B17," #.##0,00"),0))) -> PAGAR 22,99 | M17: =+IF(M$2=$E17,$D17,IF(M$2>M$257,0,IF($C17=M$2,"PAGAR"&" "&TEXT($B17," #.##0,00"),0))) -> 0 | N17: =+IF(N$2=$E17,$D17,IF(N$2>N$257,0,IF($C17=N$2,"PAGAR"&" "&TEXT($B17," #.##0,00"),0))) -> 0 | O17: =+IF(O$2=$E17,$D17,IF(O$2>O$257,0,IF($C17=O$2,"PAGAR"&" "&TEXT($B17," #.##0,00"),0))) -> 0 | P17: =+IF(P$2=$E17,$D17,IF(P$2>P$257,0,IF($C17=P$2,"PAGAR"&" "&TEXT($B17," #.##0,00"),0))) -> 0 | Q17: =+IF(Q$2=$E17,$D17,IF(Q$2>Q$257,0,IF($C17=Q$2,"PAGAR"&" "&TEXT($B17," #.##0,00"),0))) -> 0 | ... AM17: =+IF(AM$2=$E17,$D17,IF(AM$2>AM$257,0,IF($C17=AM$2,"PAGAR"&" "&TEXT($B17," #.##0,00"),0))) -> 0 | AN17: =+IF(F17<0,-F17,0) -> 0 | AO17: =+IF(AND(C17=0,B17>0),B17,0) -> 0 | AS17: CPFL Barão | AT17: 8042.83 | AU17: Fernando | AV17: 1081 | AW17: 5asec advogados (22/22parcelas) | AX17: 3030.3 | AY17: Frees + R$400 Josiane | AZ17: 6900 | BA17: CPFL Sunset | BB17: 596.7
A18: Microsoft Office - Cartão | B18: 60 | C18: 3 | F18: =+IF(TODAY()<DATEVALUE(1&D$1&E$1),0,IF(C18>0,IF(C18-SUM(I$255:AM$255)<0,B18-SUM(I18:AM18,0),0),0))+IF(C18=-1,B18-SUM(J18:AM18)) -> 60 | G18: =+IF(B18=0,"-",D18/B18) -> 0 | I18: =IF(I$2=$E18,$D18,IF(I$2>I$257,0,IF($C18=I$2,"PAGAR"&" "&TEXT($B18," #.##0,00"),IF($C18=-1,"PAGAR"&" "&TEXT($B18," #.##0,00"),0)))) -> 0 | J18: =+IF(J$2=$E18,$D18,IF(J$2>J$257,0,IF($C18=J$2,"PAGAR"&" "&TEXT($B18," #.##0,00"),0))) -> 0 | K18: =+IF(K$2=$E18,$D18,IF(K$2>K$257,0,IF($C18=K$2,"PAGAR"&" "&TEXT($B18," #.##0,00"),0))) -> PAGAR 60,00 | L18: =+IF(L$2=$E18,$D18,IF(L$2>L$257,0,IF($C18=L$2,"PAGAR"&" "&TEXT($B18," #.##0,00"),0))) -> 0 | M18: =+IF(M$2=$E18,$D18,IF(M$2>M$257,0,IF($C18=M$2,"PAGAR"&" "&TEXT($B18," #.##0,00"),0))) -> 0 | N18: =+IF(N$2=$E18,$D18,IF(N$2>N$257,0,IF($C18=N$2,"PAGAR"&" "&TEXT($B18," #.##0,00"),0))) -> 0 | O18: =+IF(O$2=$E18,$D18,IF(O$2>O$257,0,IF($C18=O$2,"PAGAR"&" "&TEXT($B18," #.##0,00"),0))) -> 0 | P18: =+IF(P$2=$E18,$D18,IF(P$2>P$257,0,IF($C18=P$2,"PAGAR"&" "&TEXT($B18," #.##0,00"),0))) -> 0 | Q18: =+IF(Q$2=$E18,$D18,IF(Q$2>Q$257,0,IF($C18=Q$2,"PAGAR"&" "&TEXT($B18," #.##0,00"),0))) -> 0 | ... AM18: =+IF(AM$2=$E18,$D18,IF(AM$2>AM$257,0,IF($C18=AM$2,"PAGAR"&" "&TEXT($B18," #.##0,00"),0))) -> 0 | AN18: =+IF(F18<0,-F18,0) -> 0 | AO18: =+IF(AND(C18=0,B18>0),B18,0) -> 0 | AW18: Sunset Aluguel | AX18: 3624
F19: =+IF(TODAY()<DATEVALUE(1&D$1&E$1),0,IF(C19>0,IF(C19-SUM(I$255:AM$255)<0,B19-SUM(I19:AM19,0),0),0))+IF(C19=-1,B19-SUM(J19:AM19)) -> 0 | G19: =+IF(B19=0,"-",D19/B19) -> - | I19: =IF(I$2=$E19,$D19,IF(I$2>I$257,0,IF($C19=I$2,"PAGAR"&" "&TEXT($B19," #.##0,00"),IF($C19=-1,"PAGAR"&" "&TEXT($B19," #.##0,00"),0)))) -> 0 | J19: =+IF(J$2=$E19,$D19,IF(J$2>J$257,0,IF($C19=J$2,"PAGAR"&" "&TEXT($B19," #.##0,00"),0))) -> 0 | K19: =+IF(K$2=$E19,$D19,IF(K$2>K$257,0,IF($C19=K$2,"PAGAR"&" "&TEXT($B19," #.##0,00"),0))) -> 0 | L19: =+IF(L$2=$E19,$D19,IF(L$2>L$257,0,IF($C19=L$2,"PAGAR"&" "&TEXT($B19," #.##0,00"),0))) -> 0 | M19: =+IF(M$2=$E19,$D19,IF(M$2>M$257,0,IF($C19=M$2,"PAGAR"&" "&TEXT($B19," #.##0,00"),0))) -> 0 | N19: =+IF(N$2=$E19,$D19,IF(N$2>N$257,0,IF($C19=N$2,"PAGAR"&" "&TEXT($B19," #.##0,00"),0))) -> 0 | O19: =+IF(O$2=$E19,$D19,IF(O$2>O$257,0,IF($C19=O$2,"PAGAR"&" "&TEXT($B19," #.##0,00"),0))) -> 0 | P19: =+IF(P$2=$E19,$D19,IF(P$2>P$257,0,IF($C19=P$2,"PAGAR"&" "&TEXT($B19," #.##0,00"),0))) -> 0 | Q19: =+IF(Q$2=$E19,$D19,IF(Q$2>Q$257,0,IF($C19=Q$2,"PAGAR"&" "&TEXT($B19," #.##0,00"),0))) -> 0 | ... AM19: =+IF(AM$2=$E19,$D19,IF(AM$2>AM$257,0,IF($C19=AM$2,"PAGAR"&" "&TEXT($B19," #.##0,00"),0))) -> 0 | AN19: =+IF(F19<0,-F19,0) -> 0 | AO19: =+IF(AND(C19=0,B19>0),B19,0) -> 0
F20: =+IF(TODAY()<DATEVALUE(1&D$1&E$1),0,IF(C20>0,IF(C20-SUM(I$255:AM$255)<0,B20-SUM(I20:AM20,0),0),0))+IF(C20=-1,B20-SUM(J20:AM20)) -> 0 | G20: =+IF(B20=0,"-",D20/B20) -> - | I20: =IF(I$2=$E20,$D20,IF(I$2>I$257,0,IF($C20=I$2,"PAGAR"&" "&TEXT($B20," #.##0,00"),IF($C20=-1,"PAGAR"&" "&TEXT($B20," #.##0,00"),0)))) -> 0 | J20: =+IF(J$2=$E20,$D20,IF(J$2>J$257,0,IF($C20=J$2,"PAGAR"&" "&TEXT($B20," #.##0,00"),0))) -> 0 | K20: =+IF(K$2=$E20,$D20,IF(K$2>K$257,0,IF($C20=K$2,"PAGAR"&" "&TEXT($B20," #.##0,00"),0))) -> 0 | L20: =+IF(L$2=$E20,$D20,IF(L$2>L$257,0,IF($C20=L$2,"PAGAR"&" "&TEXT($B20," #.##0,00"),0))) -> 0 | M20: =+IF(M$2=$E20,$D20,IF(M$2>M$257,0,IF($C20=M$2,"PAGAR"&" "&TEXT($B20," #.##0,00"),0))) -> 0 | N20: =+IF(N$2=$E20,$D20,IF(N$2>N$257,0,IF($C20=N$2,"PAGAR"&" "&TEXT($B20," #.##0,00"),0))) -> 0 | O20: =+IF(O$2=$E20,$D20,IF(O$2>O$257,0,IF($C20=O$2,"PAGAR"&" "&TEXT($B20," #.##0,00"),0))) -> 0 | P20: =+IF(P$2=$E20,$D20,IF(P$2>P$257,0,IF($C20=P$2,"PAGAR"&" "&TEXT($B20," #.##0,00"),0))) -> 0 | Q20: =+IF(Q$2=$E20,$D20,IF(Q$2>Q$257,0,IF($C20=Q$2,"PAGAR"&" "&TEXT($B20," #.##0,00"),0))) -> 0 | ... AM20: =+IF(AM$2=$E20,$D20,IF(AM$2>AM$257,0,IF($C20=AM$2,"PAGAR"&" "&TEXT($B20," #.##0,00"),0))) -> 0 | AN20: =+IF(F20<0,-F20,0) -> 0 | AO20: =+IF(AND(C20=0,B20>0),B20,0) -> 0
F21: =+IF(TODAY()<DATEVALUE(1&D$1&E$1),0,IF(C21>0,IF(C21-SUM(I$255:AM$255)<0,B21-SUM(I21:AM21,0),0),0))+IF(C21=-1,B21-SUM(J21:AM21)) -> 0 | G21: =+IF(B21=0,"-",D21/B21) -> - | I21: =IF(I$2=$E21,$D21,IF(I$2>I$257,0,IF($C21=I$2,"PAGAR"&" "&TEXT($B21," #.##0,00"),IF($C21=-1,"PAGAR"&" "&TEXT($B21," #.##0,00"),0)))) -> 0 | J21: =+IF(J$2=$E21,$D21,IF(J$2>J$257,0,IF($C21=J$2,"PAGAR"&" "&TEXT($B21," #.##0,00"),0))) -> 0 | K21: =+IF(K$2=$E21,$D21,IF(K$2>K$257,0,IF($C21=K$2,"PAGAR"&" "&TEXT($B21," #.##0,00"),0))) -> 0 | L21: =+IF(L$2=$E21,$D21,IF(L$2>L$257,0,IF($C21=L$2,"PAGAR"&" "&TEXT($B21," #.##0,00"),0))) -> 0 | M21: =+IF(M$2=$E21,$D21,IF(M$2>M$257,0,IF($C21=M$2,"PAGAR"&" "&TEXT($B21," #.##0,00"),0))) -> 0 | N21: =+IF(N$2=$E21,$D21,IF(N$2>N$257,0,IF($C21=N$2,"PAGAR"&" "&TEXT($B21," #.##0,00"),0))) -> 0 | O21: =+IF(O$2=$E21,$D21,IF(O$2>O$257,0,IF($C21=O$2,"PAGAR"&" "&TEXT($B21," #.##0,00"),0))) -> 0 | P21: =+IF(P$2=$E21,$D21,IF(P$2>P$257,0,IF($C21=P$2,"PAGAR"&" "&TEXT($B21," #.##0,00"),0))) -> 0 | Q21: =+IF(Q$2=$E21,$D21,IF(Q$2>Q$257,0,IF($C21=Q$2,"PAGAR"&" "&TEXT($B21," #.##0,00"),0))) -> 0 | ... AM21: =+IF(AM$2=$E21,$D21,IF(AM$2>AM$257,0,IF($C21=AM$2,"PAGAR"&" "&TEXT($B21," #.##0,00"),0))) -> 0 | AN21: =+IF(F21<0,-F21,0) -> 0 | AO21: =+IF(AND(C21=0,B21>0),B21,0) -> 0
F22: =+IF(TODAY()<DATEVALUE(1&D$1&E$1),0,IF(C22>0,IF(C22-SUM(I$255:AM$255)<0,B22-SUM(I22:AM22,0),0),0))+IF(C22=-1,B22-SUM(J22:AM22)) -> 0 | G22: =+IF(B22=0,"-",D22/B22) -> - | I22: =IF(I$2=$E22,$D22,IF(I$2>I$257,0,IF($C22=I$2,"PAGAR"&" "&TEXT($B22," #.##0,00"),IF($C22=-1,"PAGAR"&" "&TEXT($B22," #.##0,00"),0)))) -> 0 | J22: =+IF(J$2=$E22,$D22,IF(J$2>J$257,0,IF($C22=J$2,"PAGAR"&" "&TEXT($B22," #.##0,00"),0))) -> 0 | K22: =+IF(K$2=$E22,$D22,IF(K$2>K$257,0,IF($C22=K$2,"PAGAR"&" "&TEXT($B22," #.##0,00"),0))) -> 0 | L22: =+IF(L$2=$E22,$D22,IF(L$2>L$257,0,IF($C22=L$2,"PAGAR"&" "&TEXT($B22," #.##0,00"),0))) -> 0 | M22: =+IF(M$2=$E22,$D22,IF(M$2>M$257,0,IF($C22=M$2,"PAGAR"&" "&TEXT($B22," #.##0,00"),0))) -> 0 | N22: =+IF(N$2=$E22,$D22,IF(N$2>N$257,0,IF($C22=N$2,"PAGAR"&" "&TEXT($B22," #.##0,00"),0))) -> 0 | O22: =+IF(O$2=$E22,$D22,IF(O$2>O$257,0,IF($C22=O$2,"PAGAR"&" "&TEXT($B22," #.##0,00"),0))) -> 0 | P22: =+IF(P$2=$E22,$D22,IF(P$2>P$257,0,IF($C22=P$2,"PAGAR"&" "&TEXT($B22," #.##0,00"),0))) -> 0 | Q22: =+IF(Q$2=$E22,$D22,IF(Q$2>Q$257,0,IF($C22=Q$2,"PAGAR"&" "&TEXT($B22," #.##0,00"),0))) -> 0 | ... AM22: =+IF(AM$2=$E22,$D22,IF(AM$2>AM$257,0,IF($C22=AM$2,"PAGAR"&" "&TEXT($B22," #.##0,00"),0))) -> 0 | AN22: =+IF(F22<0,-F22,0) -> 0 | AO22: =+IF(AND(C22=0,B22>0),B22,0) -> 0
F23: =+IF(TODAY()<DATEVALUE(1&D$1&E$1),0,IF(C23>0,IF(C23-SUM(I$255:AM$255)<0,B23-SUM(I23:AM23,0),0),0))+IF(C23=-1,B23-SUM(J23:AM23)) -> 0 | G23: =+IF(B23=0,"-",D23/B23) -> - | I23: =IF(I$2=$E23,$D23,IF(I$2>I$257,0,IF($C23=I$2,"PAGAR"&" "&TEXT($B23," #.##0,00"),IF($C23=-1,"PAGAR"&" "&TEXT($B23," #.##0,00"),0)))) -> 0 | J23: =+IF(J$2=$E23,$D23,IF(J$2>J$257,0,IF($C23=J$2,"PAGAR"&" "&TEXT($B23," #.##0,00"),0))) -> 0 | K23: =+IF(K$2=$E23,$D23,IF(K$2>K$257,0,IF($C23=K$2,"PAGAR"&" "&TEXT($B23," #.##0,00"),0))) -> 0 | L23: =+IF(L$2=$E23,$D23,IF(L$2>L$257,0,IF($C23=L$2,"PAGAR"&" "&TEXT($B23," #.##0,00"),0))) -> 0 | M23: =+IF(M$2=$E23,$D23,IF(M$2>M$257,0,IF($C23=M$2,"PAGAR"&" "&TEXT($B23," #.##0,00"),0))) -> 0 | N23: =+IF(N$2=$E23,$D23,IF(N$2>N$257,0,IF($C23=N$2,"PAGAR"&" "&TEXT($B23," #.##0,00"),0))) -> 0 | O23: =+IF(O$2=$E23,$D23,IF(O$2>O$257,0,IF($C23=O$2,"PAGAR"&" "&TEXT($B23," #.##0,00"),0))) -> 0 | P23: =+IF(P$2=$E23,$D23,IF(P$2>P$257,0,IF($C23=P$2,"PAGAR"&" "&TEXT($B23," #.##0,00"),0))) -> 0 | Q23: =+IF(Q$2=$E23,$D23,IF(Q$2>Q$257,0,IF($C23=Q$2,"PAGAR"&" "&TEXT($B23," #.##0,00"),0))) -> 0 | ... AM23: =+IF(AM$2=$E23,$D23,IF(AM$2>AM$257,0,IF($C23=AM$2,"PAGAR"&" "&TEXT($B23," #.##0,00"),0))) -> 0 | AN23: =+IF(F23<0,-F23,0) -> 0 | AO23: =+IF(AND(C23=0,B23>0),B23,0) -> 0
F24: =+IF(TODAY()<DATEVALUE(1&D$1&E$1),0,IF(C24>0,IF(C24-SUM(I$255:AM$255)<0,B24-SUM(I24:AM24,0),0),0))+IF(C24=-1,B24-SUM(J24:AM24)) -> 0 | G24: =+IF(B24=0,"-",D24/B24) -> - | I24: =IF(I$2=$E24,$D24,IF(I$2>I$257,0,IF($C24=I$2,"PAGAR"&" "&TEXT($B24," #.##0,00"),IF($C24=-1,"PAGAR"&" "&TEXT($B24," #.##0,00"),0)))) -> 0 | J24: =+IF(J$2=$E24,$D24,IF(J$2>J$257,0,IF($C24=J$2,"PAGAR"&" "&TEXT($B24," #.##0,00"),0))) -> 0 | K24: =+IF(K$2=$E24,$D24,IF(K$2>K$257,0,IF($C24=K$2,"PAGAR"&" "&TEXT($B24," #.##0,00"),0))) -> 0 | L24: =+IF(L$2=$E24,$D24,IF(L$2>L$257,0,IF($C24=L$2,"PAGAR"&" "&TEXT($B24," #.##0,00"),0))) -> 0 | M24: =+IF(M$2=$E24,$D24,IF(M$2>M$257,0,IF($C24=M$2,"PAGAR"&" "&TEXT($B24," #.##0,00"),0))) -> 0 | N24: =+IF(N$2=$E24,$D24,IF(N$2>N$257,0,IF($C24=N$2,"PAGAR"&" "&TEXT($B24," #.##0,00"),0))) -> 0 | O24: =+IF(O$2=$E24,$D24,IF(O$2>O$257,0,IF($C24=O$2,"PAGAR"&" "&TEXT($B24," #.##0,00"),0))) -> 0 | P24: =+IF(P$2=$E24,$D24,IF(P$2>P$257,0,IF($C24=P$2,"PAGAR"&" "&TEXT($B24," #.##0,00"),0))) -> 0 | Q24: =+IF(Q$2=$E24,$D24,IF(Q$2>Q$257,0,IF($C24=Q$2,"PAGAR"&" "&TEXT($B24," #.##0,00"),0))) -> 0 | ... AM24: =+IF(AM$2=$E24,$D24,IF(AM$2>AM$257,0,IF($C24=AM$2,"PAGAR"&" "&TEXT($B24," #.##0,00"),0))) -> 0 | AN24: =+IF(F24<0,-F24,0) -> 0 | AO24: =+IF(AND(C24=0,B24>0),B24,0) -> 0
F25: =+IF(TODAY()<DATEVALUE(1&D$1&E$1),0,IF(C25>0,IF(C25-SUM(I$255:AM$255)<0,B25-SUM(I25:AM25,0),0),0))+IF(C25=-1,B25-SUM(J25:AM25)) -> 0 | G25: =+IF(B25=0,"-",D25/B25) -> - | I25: =IF(I$2=$E25,$D25,IF(I$2>I$257,0,IF($C25=I$2,"PAGAR"&" "&TEXT($B25," #.##0,00"),IF($C25=-1,"PAGAR"&" "&TEXT($B25," #.##0,00"),0)))) -> 0 | J25: =+IF(J$2=$E25,$D25,IF(J$2>J$257,0,IF($C25=J$2,"PAGAR"&" "&TEXT($B25," #.##0,00"),0))) -> 0 | K25: =+IF(K$2=$E25,$D25,IF(K$2>K$257,0,IF($C25=K$2,"PAGAR"&" "&TEXT($B25," #.##0,00"),0))) -> 0 | L25: =+IF(L$2=$E25,$D25,IF(L$2>L$257,0,IF($C25=L$2,"PAGAR"&" "&TEXT($B25," #.##0,00"),0))) -> 0 | M25: =+IF(M$2=$E25,$D25,IF(M$2>M$257,0,IF($C25=M$2,"PAGAR"&" "&TEXT($B25," #.##0,00"),0))) -> 0 | N25: =+IF(N$2=$E25,$D25,IF(N$2>N$257,0,IF($C25=N$2,"PAGAR"&" "&TEXT($B25," #.##0,00"),0))) -> 0 | O25: =+IF(O$2=$E25,$D25,IF(O$2>O$257,0,IF($C25=O$2,"PAGAR"&" "&TEXT($B25," #.##0,00"),0))) -> 0 | P25: =+IF(P$2=$E25,$D25,IF(P$2>P$257,0,IF($C25=P$2,"PAGAR"&" "&TEXT($B25," #.##0,00"),0))) -> 0 | Q25: =+IF(Q$2=$E25,$D25,IF(Q$2>Q$257,0,IF($C25=Q$2,"PAGAR"&" "&TEXT($B25," #.##0,00"),0))) -> 0 | ... AM25: =+IF(AM$2=$E25,$D25,IF(AM$2>AM$257,0,IF($C25=AM$2,"PAGAR"&" "&TEXT($B25," #.##0,00"),0))) -> 0 | AN25: =+IF(F25<0,-F25,0) -> 0 | AO25: =+IF(AND(C25=0,B25>0),B25,0) -> 0
A26: Total de despesas previstas (Plan 2) | B26: =+SUM(B5:B25) -> 17706.7 | D26: =+SUM(D5:D25) -> 8190.14 | F26: =+SUMIF(F5:F25,">0") -> 6499.2 | G26: =+IF(B26=0,"-",D26/B26) -> 0.46254469 | I26: =+PLAN2!H27 -> 0 | J26: =+PLAN2!I27 -> 6650 | K26: =+PLAN2!J27 -> 65.9 | L26: =+PLAN2!K27 -> 22.99 | M26: =+PLAN2!L27 -> 5.9 | N26: =+PLAN2!M27 -> 0 | O26: =+PLAN2!N27 -> 6404.41 | P26: =+PLAN2!O27 -> 0 | ... AM26: =+PLAN2!AL27 -> 0 | AN26: =SUM(AN5:AN25) -> 0 | AQ26: =+W2 -> 15 | AS26: =+X2 -> 16 | AU26: =+Y2 -> 17 | AW26: =+Z2 -> 18 | AY26: =+AA2 -> 19 | BA26: =+AB2 -> 20 | BC26: =+AC2 -> 21
A27: EXTRA EMPRESA | AQ27: {=_xlfn._xlws.FILTER($A$5:$A$152,$C$5:$C$152=AQ26,"livre")} -> Cristiane | AR27: {=_xlfn._xlws.FILTER($B$5:$B$152,$C$5:$C$152=AQ26,"livre")} -> 940 | AS27: {=_xlfn._xlws.FILTER($A$5:$A$152,$C$5:$C$152=AS26,"livre")} -> livre | AT27: {=_xlfn._xlws.FILTER($B$5:$B$152,$C$5:$C$152=AS26,"livre")} -> livre | AU27: {=_xlfn._xlws.FILTER($A$5:$A$152,$C$5:$C$152=AU26,"livre")} -> Convênio Tina | AV27: {=_xlfn._xlws.FILTER($B$5:$B$152,$C$5:$C$152=AU26,"livre")} -> 1010 | AW27: {=_xlfn._xlws.FILTER($A$5:$A$152,$C$5:$C$152=AW26,"livre")} -> livre | AX27: {=_xlfn._xlws.FILTER($B$5:$B$152,$C$5:$C$152=AW26,"livre")} -> livre | AY27: {=_xlfn._xlws.FILTER($A$5:$A$152,$C$5:$C$152=AY26,"livre")} -> Frees + R$400 Josiane | AZ27: {=_xlfn._xlws.FILTER($B$5:$B$152,$C$5:$C$152=AY26,"livre")} -> 6900 | BA27: {=_xlfn._xlws.FILTER($A$5:$A$152,$C$5:$C$152=BA26,"livre")} -> Francisca | BB27: {=_xlfn._xlws.FILTER($B$5:$B$152,$C$5:$C$152=BA26,"livre")} -> 720 | BC27: {=_xlfn._xlws.FILTER($A$5:$A$152,$C$5:$C$152=BC26,"livre")} -> livre | BD27: {=_xlfn._xlws.FILTER($B$5:$B$152,$C$5:$C$152=BC26,"livre")} -> livre
A28: Escritório Aluguel | B28: 2945.42 | C28: 11 | F28: =+IF(TODAY()<DATEVALUE(1&D$1&E$1),0,IF(C28>0,IF(C28-SUM(I$255:AM$255)<0,B28-SUM(I28:AM28,0),0),0))+IF(C28=-1,B28-SUM(J28:AM28)) -> 2945.42 | G28: =+IF(B28=0,"-",D28/B28) -> 0 | H28: =IF(H$2=$E28,$D28,IF(H$2>H$257,0,IF($C28=H$2,"PAGAR"&" "&TEXT($B28," #.##0,00"),IF($C28=-1,"PAGAR"&" "&TEXT($B28," #.##0,00"),0)))) -> 0 | I28: =IF(I$2=$E28,$D28,IF(I$2>I$257,0,IF($C28=I$2,"PAGAR"&" "&TEXT($B28," #.##0,00"),IF($C28=-1,"PAGAR"&" "&TEXT($B28," #.##0,00"),0)))) -> 0 | J28: =+IF(J$2=$E28,$D28,IF(J$2>J$257,0,IF($C28=J$2,"PAGAR"&" "&TEXT($B28," #.##0,00"),0))) -> 0 | K28: =+IF(K$2=$E28,$D28,IF(K$2>K$257,0,IF($C28=K$2,"PAGAR"&" "&TEXT($B28," #.##0,00"),0))) -> 0 | L28: =+IF(L$2=$E28,$D28,IF(L$2>L$257,0,IF($C28=L$2,"PAGAR"&" "&TEXT($B28," #.##0,00"),0))) -> 0 | M28: =+IF(M$2=$E28,$D28,IF(M$2>M$257,0,IF($C28=M$2,"PAGAR"&" "&TEXT($B28," #.##0,00"),0))) -> 0 | N28: =+IF(N$2=$E28,$D28,IF(N$2>N$257,0,IF($C28=N$2,"PAGAR"&" "&TEXT($B28," #.##0,00"),0))) -> 0 | O28: =+IF(O$2=$E28,$D28,IF(O$2>O$257,0,IF($C28=O$2,"PAGAR"&" "&TEXT($B28," #.##0,00"),0))) -> 0 | P28: =+IF(P$2=$E28,$D28,IF(P$2>P$257,0,IF($C28=P$2,"PAGAR"&" "&TEXT($B28," #.##0,00"),0))) -> 0 | Q28: =+IF(Q$2=$E28,$D28,IF(Q$2>Q$257,0,IF($C28=Q$2,"PAGAR"&" "&TEXT($B28," #.##0,00"),0))) -> 0 | ... AM28: =+IF(AM$2=$E28,$D28,IF(AM$2>AM$257,0,IF($C28=AM$2,"PAGAR"&" "&TEXT($B28," #.##0,00"),0))) -> 0 | AN28: =+IF(F28<0,-F28,0) -> 0 | AO28: =+IF(AND(C28=0,B28>0),B28,0) -> 0 | AQ28: Bônus Adriano | AR28: 500 | BA28: 4 Lock -- adiant | BB28: 12000
A29: Água Barão | B29: 2775 | C29: 26 | F29: =+IF(TODAY()<DATEVALUE(1&D$1&E$1),0,IF(C29>0,IF(C29-SUM(I$255:AM$255)<0,B29-SUM(I29:AM29,0),0),0))+IF(C29=-1,B29-SUM(J29:AM29)) -> 0 | G29: =+IF(B29=0,"-",D29/B29) -> 0 | H29: =IF(H$2=$E29,$D29,IF(H$2>H$257,0,IF($C29=H$2,"PAGAR"&" "&TEXT($B29," #.##0,00"),IF($C29=-1,"PAGAR"&" "&TEXT($B29," #.##0,00"),0)))) -> 0 | I29: =IF(I$2=$E29,$D29,IF(I$2>I$257,0,IF($C29=I$2,"PAGAR"&" "&TEXT($B29," #.##0,00"),IF($C29=-1,"PAGAR"&" "&TEXT($B29," #.##0,00"),0)))) -> 0 | J29: =+IF(J$2=$E29,$D29,IF(J$2>J$257,0,IF($C29=J$2,"PAGAR"&" "&TEXT($B29," #.##0,00"),0))) -> 0 | K29: =+IF(K$2=$E29,$D29,IF(K$2>K$257,0,IF($C29=K$2,"PAGAR"&" "&TEXT($B29," #.##0,00"),0))) -> 0 | L29: =+IF(L$2=$E29,$D29,IF(L$2>L$257,0,IF($C29=L$2,"PAGAR"&" "&TEXT($B29," #.##0,00"),0))) -> 0 | M29: =+IF(M$2=$E29,$D29,IF(M$2>M$257,0,IF($C29=M$2,"PAGAR"&" "&TEXT($B29," #.##0,00"),0))) -> 0 | N29: =+IF(N$2=$E29,$D29,IF(N$2>N$257,0,IF($C29=N$2,"PAGAR"&" "&TEXT($B29," #.##0,00"),0))) -> 0 | O29: =+IF(O$2=$E29,$D29,IF(O$2>O$257,0,IF($C29=O$2,"PAGAR"&" "&TEXT($B29," #.##0,00"),0))) -> 0 | P29: =+IF(P$2=$E29,$D29,IF(P$2>P$257,0,IF($C29=P$2,"PAGAR"&" "&TEXT($B29," #.##0,00"),0))) -> 0 | Q29: =+IF(Q$2=$E29,$D29,IF(Q$2>Q$257,0,IF($C29=Q$2,"PAGAR"&" "&TEXT($B29," #.##0,00"),0))) -> 0 | ... AM29: =+IF(AM$2=$E29,$D29,IF(AM$2>AM$257,0,IF($C29=AM$2,"PAGAR"&" "&TEXT($B29," #.##0,00"),0))) -> 0 | AN29: =+IF(F29<0,-F29,0) -> 0 | AO29: =+IF(AND(C29=0,B29>0),B29,0) -> 0 | AQ29: Bônus Tamara | AR29: 569 | BA29: Perfecto -- adiant | BB29: 1500 | BK29: =+AK2 -> 29 | BL29: =+AL2 -> 30
A30: Cristiane | B30: 940 | C30: 15 | F30: =+IF(TODAY()<DATEVALUE(1&D$1&E$1),0,IF(C30>0,IF(C30-SUM(I$255:AM$255)<0,B30-SUM(I30:AM30,0),0),0))+IF(C30=-1,B30-SUM(J30:AM30)) -> 0 | G30: =+IF(B30=0,"-",D30/B30) -> 0 | H30: =IF(H$2=$E30,$D30,IF(H$2>H$257,0,IF($C30=H$2,"PAGAR"&" "&TEXT($B30," #.##0,00"),IF($C30=-1,"PAGAR"&" "&TEXT($B30," #.##0,00"),0)))) -> 0 | I30: =IF(I$2=$E30,$D30,IF(I$2>I$257,0,IF($C30=I$2,"PAGAR"&" "&TEXT($B30," #.##0,00"),IF($C30=-1,"PAGAR"&" "&TEXT($B30," #.##0,00"),0)))) -> 0 | J30: =+IF(J$2=$E30,$D30,IF(J$2>J$257,0,IF($C30=J$2,"PAGAR"&" "&TEXT($B30," #.##0,00"),0))) -> 0 | K30: =+IF(K$2=$E30,$D30,IF(K$2>K$257,0,IF($C30=K$2,"PAGAR"&" "&TEXT($B30," #.##0,00"),0))) -> 0 | L30: =+IF(L$2=$E30,$D30,IF(L$2>L$257,0,IF($C30=L$2,"PAGAR"&" "&TEXT($B30," #.##0,00"),0))) -> 0 | M30: =+IF(M$2=$E30,$D30,IF(M$2>M$257,0,IF($C30=M$2,"PAGAR"&" "&TEXT($B30," #.##0,00"),0))) -> 0 | N30: =+IF(N$2=$E30,$D30,IF(N$2>N$257,0,IF($C30=N$2,"PAGAR"&" "&TEXT($B30," #.##0,00"),0))) -> 0 | O30: =+IF(O$2=$E30,$D30,IF(O$2>O$257,0,IF($C30=O$2,"PAGAR"&" "&TEXT($B30," #.##0,00"),0))) -> 0 | P30: =+IF(P$2=$E30,$D30,IF(P$2>P$257,0,IF($C30=P$2,"PAGAR"&" "&TEXT($B30," #.##0,00"),0))) -> 0 | Q30: =+IF(Q$2=$E30,$D30,IF(Q$2>Q$257,0,IF($C30=Q$2,"PAGAR"&" "&TEXT($B30," #.##0,00"),0))) -> 0 | ... AM30: =+IF(AM$2=$E30,$D30,IF(AM$2>AM$257,0,IF($C30=AM$2,"PAGAR"&" "&TEXT($B30," #.##0,00"),0))) -> 0 | AN30: =+IF(F30<0,-F30,0) -> 0 | AO30: =+IF(AND(C30=0,B30>0),B30,0) -> 0 | AQ30: VT | AR30: 500
A31: Cristiane | B31: 940 | C31: 30 | F31: =+IF(TODAY()<DATEVALUE(1&D$1&E$1),0,IF(C31>0,IF(C31-SUM(I$255:AM$255)<0,B31-SUM(I31:AM31,0),0),0))+IF(C31=-1,B31-SUM(J31:AM31)) -> 0 | G31: =+IF(B31=0,"-",D31/B31) -> 0 | H31: =IF(H$2=$E31,$D31,IF(H$2>H$257,0,IF($C31=H$2,"PAGAR"&" "&TEXT($B31," #.##0,00"),IF($C31=-1,"PAGAR"&" "&TEXT($B31," #.##0,00"),0)))) -> 0 | I31: =IF(I$2=$E31,$D31,IF(I$2>I$257,0,IF($C31=I$2,"PAGAR"&" "&TEXT($B31," #.##0,00"),IF($C31=-1,"PAGAR"&" "&TEXT($B31," #.##0,00"),0)))) -> 0 | J31: =+IF(J$2=$E31,$D31,IF(J$2>J$257,0,IF($C31=J$2,"PAGAR"&" "&TEXT($B31," #.##0,00"),0))) -> 0 | K31: =+IF(K$2=$E31,$D31,IF(K$2>K$257,0,IF($C31=K$2,"PAGAR"&" "&TEXT($B31," #.##0,00"),0))) -> 0 | L31: =+IF(L$2=$E31,$D31,IF(L$2>L$257,0,IF($C31=L$2,"PAGAR"&" "&TEXT($B31," #.##0,00"),0))) -> 0 | M31: =+IF(M$2=$E31,$D31,IF(M$2>M$257,0,IF($C31=M$2,"PAGAR"&" "&TEXT($B31," #.##0,00"),0))) -> 0 | N31: =+IF(N$2=$E31,$D31,IF(N$2>N$257,0,IF($C31=N$2,"PAGAR"&" "&TEXT($B31," #.##0,00"),0))) -> 0 | O31: =+IF(O$2=$E31,$D31,IF(O$2>O$257,0,IF($C31=O$2,"PAGAR"&" "&TEXT($B31," #.##0,00"),0))) -> 0 | P31: =+IF(P$2=$E31,$D31,IF(P$2>P$257,0,IF($C31=P$2,"PAGAR"&" "&TEXT($B31," #.##0,00"),0))) -> 0 | Q31: =+IF(Q$2=$E31,$D31,IF(Q$2>Q$257,0,IF($C31=Q$2,"PAGAR"&" "&TEXT($B31," #.##0,00"),0))) -> 0 | ... AM31: =+IF(AM$2=$E31,$D31,IF(AM$2>AM$257,0,IF($C31=AM$2,"PAGAR"&" "&TEXT($B31," #.##0,00"),0))) -> 0 | AN31: =+IF(F31<0,-F31,0) -> 0 | AO31: =+IF(AND(C31=0,B31>0),B31,0) -> 0 | AQ31: Naturgy - estimado | AR31: 220
A32: Francisca | B32: 1080 | C32: 6 | F32: =+IF(TODAY()<DATEVALUE(1&D$1&E$1),0,IF(C32>0,IF(C32-SUM(I$255:AM$255)<0,B32-SUM(I32:AM32,0),0),0))+IF(C32=-1,B32-SUM(J32:AM32)) -> 1080 | G32: =+IF(B32=0,"-",D32/B32) -> 0 | H32: =IF(H$2=$E32,$D32,IF(H$2>H$257,0,IF($C32=H$2,"PAGAR"&" "&TEXT($B32," #.##0,00"),IF($C32=-1,"PAGAR"&" "&TEXT($B32," #.##0,00"),0)))) -> 0 | I32: =IF(I$2=$E32,$D32,IF(I$2>I$257,0,IF($C32=I$2,"PAGAR"&" "&TEXT($B32," #.##0,00"),IF($C32=-1,"PAGAR"&" "&TEXT($B32," #.##0,00"),0)))) -> 0 | J32: =+IF(J$2=$E32,$D32,IF(J$2>J$257,0,IF($C32=J$2,"PAGAR"&" "&TEXT($B32," #.##0,00"),0))) -> 0 | K32: =+IF(K$2=$E32,$D32,IF(K$2>K$257,0,IF($C32=K$2,"PAGAR"&" "&TEXT($B32," #.##0,00"),0))) -> 0 | L32: =+IF(L$2=$E32,$D32,IF(L$2>L$257,0,IF($C32=L$2,"PAGAR"&" "&TEXT($B32," #.##0,00"),0))) -> 0 | M32: =+IF(M$2=$E32,$D32,IF(M$2>M$257,0,IF($C32=M$2,"PAGAR"&" "&TEXT($B32," #.##0,00"),0))) -> 0 | N32: =+IF(N$2=$E32,$D32,IF(N$2>N$257,0,IF($C32=N$2,"PAGAR"&" "&TEXT($B32," #.##0,00"),0))) -> PAGAR 1.080,00 | O32: =+IF(O$2=$E32,$D32,IF(O$2>O$257,0,IF($C32=O$2,"PAGAR"&" "&TEXT($B32," #.##0,00"),0))) -> 0 | P32: =+IF(P$2=$E32,$D32,IF(P$2>P$257,0,IF($C32=P$2,"PAGAR"&" "&TEXT($B32," #.##0,00"),0))) -> 0 | Q32: =+IF(Q$2=$E32,$D32,IF(Q$2>Q$257,0,IF($C32=Q$2,"PAGAR"&" "&TEXT($B32," #.##0,00"),0))) -> 0 | ... AM32: =+IF(AM$2=$E32,$D32,IF(AM$2>AM$257,0,IF($C32=AM$2,"PAGAR"&" "&TEXT($B32," #.##0,00"),0))) -> 0 | AN32: =+IF(F32<0,-F32,0) -> 0 | AO32: =+IF(AND(C32=0,B32>0),B32,0) -> 0 | AQ32: Letízio ?/36 | AR32: 2750
A33: Francisca | B33: 720 | C33: 20 | F33: =+IF(TODAY()<DATEVALUE(1&D$1&E$1),0,IF(C33>0,IF(C33-SUM(I$255:AM$255)<0,B33-SUM(I33:AM33,0),0),0))+IF(C33=-1,B33-SUM(J33:AM33)) -> 0 | G33: =+IF(B33=0,"-",D33/B33) -> 0 | H33: =IF(H$2=$E33,$D33,IF(H$2>H$257,0,IF($C33=H$2,"PAGAR"&" "&TEXT($B33," #.##0,00"),IF($C33=-1,"PAGAR"&" "&TEXT($B33," #.##0,00"),0)))) -> 0 | I33: =IF(I$2=$E33,$D33,IF(I$2>I$257,0,IF($C33=I$2,"PAGAR"&" "&TEXT($B33," #.##0,00"),IF($C33=-1,"PAGAR"&" "&TEXT($B33," #.##0,00"),0)))) -> 0 | J33: =+IF(J$2=$E33,$D33,IF(J$2>J$257,0,IF($C33=J$2,"PAGAR"&" "&TEXT($B33," #.##0,00"),0))) -> 0 | K33: =+IF(K$2=$E33,$D33,IF(K$2>K$257,0,IF($C33=K$2,"PAGAR"&" "&TEXT($B33," #.##0,00"),0))) -> 0 | L33: =+IF(L$2=$E33,$D33,IF(L$2>L$257,0,IF($C33=L$2,"PAGAR"&" "&TEXT($B33," #.##0,00"),0))) -> 0 | M33: =+IF(M$2=$E33,$D33,IF(M$2>M$257,0,IF($C33=M$2,"PAGAR"&" "&TEXT($B33," #.##0,00"),0))) -> 0 | N33: =+IF(N$2=$E33,$D33,IF(N$2>N$257,0,IF($C33=N$2,"PAGAR"&" "&TEXT($B33," #.##0,00"),0))) -> 0 | O33: =+IF(O$2=$E33,$D33,IF(O$2>O$257,0,IF($C33=O$2,"PAGAR"&" "&TEXT($B33," #.##0,00"),0))) -> 0 | P33: =+IF(P$2=$E33,$D33,IF(P$2>P$257,0,IF($C33=P$2,"PAGAR"&" "&TEXT($B33," #.##0,00"),0))) -> 0 | Q33: =+IF(Q$2=$E33,$D33,IF(Q$2>Q$257,0,IF($C33=Q$2,"PAGAR"&" "&TEXT($B33," #.##0,00"),0))) -> 0 | ... AM33: =+IF(AM$2=$E33,$D33,IF(AM$2>AM$257,0,IF($C33=AM$2,"PAGAR"&" "&TEXT($B33," #.##0,00"),0))) -> 0 | AN33: =+IF(F33<0,-F33,0) -> 0 | AO33: =+IF(AND(C33=0,B33>0),B33,0) -> 0 | AQ33: Barão Aluguel | AR33: 4377.08
A34: Convênio Tina | B34: 1010 | C34: 17 | D34: 1010 | E34: 12 | F34: =+IF(TODAY()<DATEVALUE(1&D$1&E$1),0,IF(C34>0,IF(C34-SUM(I$255:AM$255)<0,B34-SUM(I34:AM34,0),0),0))+IF(C34=-1,B34-SUM(J34:AM34)) -> 0 | G34: =+IF(B34=0,"-",D34/B34) -> 1 | H34: =IF(H$2=$E34,$D34,IF(H$2>H$257,0,IF($C34=H$2,"PAGAR"&" "&TEXT($B34," #.##0,00"),IF($C34=-1,"PAGAR"&" "&TEXT($B34," #.##0,00"),0)))) -> 0 | I34: =IF(I$2=$E34,$D34,IF(I$2>I$257,0,IF($C34=I$2,"PAGAR"&" "&TEXT($B34," #.##0,00"),IF($C34=-1,"PAGAR"&" "&TEXT($B34," #.##0,00"),0)))) -> 0 | J34: =+IF(J$2=$E34,$D34,IF(J$2>J$257,0,IF($C34=J$2,"PAGAR"&" "&TEXT($B34," #.##0,00"),0))) -> 0 | K34: =+IF(K$2=$E34,$D34,IF(K$2>K$257,0,IF($C34=K$2,"PAGAR"&" "&TEXT($B34," #.##0,00"),0))) -> 0 | L34: =+IF(L$2=$E34,$D34,IF(L$2>L$257,0,IF($C34=L$2,"PAGAR"&" "&TEXT($B34," #.##0,00"),0))) -> 0 | M34: =+IF(M$2=$E34,$D34,IF(M$2>M$257,0,IF($C34=M$2,"PAGAR"&" "&TEXT($B34," #.##0,00"),0))) -> 0 | N34: =+IF(N$2=$E34,$D34,IF(N$2>N$257,0,IF($C34=N$2,"PAGAR"&" "&TEXT($B34," #.##0,00"),0))) -> 0 | O34: =+IF(O$2=$E34,$D34,IF(O$2>O$257,0,IF($C34=O$2,"PAGAR"&" "&TEXT($B34," #.##0,00"),0))) -> 0 | P34: =+IF(P$2=$E34,$D34,IF(P$2>P$257,0,IF($C34=P$2,"PAGAR"&" "&TEXT($B34," #.##0,00"),0))) -> 0 | Q34: =+IF(Q$2=$E34,$D34,IF(Q$2>Q$257,0,IF($C34=Q$2,"PAGAR"&" "&TEXT($B34," #.##0,00"),0))) -> 0 | ... AM34: =+IF(AM$2=$E34,$D34,IF(AM$2>AM$257,0,IF($C34=AM$2,"PAGAR"&" "&TEXT($B34," #.##0,00"),0))) -> 0 | AN34: =+IF(F34<0,-F34,0) -> 0 | AO34: =+IF(AND(C34=0,B34>0),B34,0) -> 0 | AQ34: Boa Vista Aluguel | AR34: 3450
A35: Bônus Adriano | B35: 500 | C35: 15 | F35: =+IF(TODAY()<DATEVALUE(1&D$1&E$1),0,IF(C35>0,IF(C35-SUM(I$255:AM$255)<0,B35-SUM(I35:AM35,0),0),0))+IF(C35=-1,B35-SUM(J35:AM35)) -> 0 | G35: =+IF(B35=0,"-",D35/B35) -> 0 | H35: =IF(H$2=$E35,$D35,IF(H$2>H$257,0,IF($C35=H$2,"PAGAR"&" "&TEXT($B35," #.##0,00"),IF($C35=-1,"PAGAR"&" "&TEXT($B35," #.##0,00"),0)))) -> 0 | I35: =IF(I$2=$E35,$D35,IF(I$2>I$257,0,IF($C35=I$2,"PAGAR"&" "&TEXT($B35," #.##0,00"),IF($C35=-1,"PAGAR"&" "&TEXT($B35," #.##0,00"),0)))) -> 0 | J35: =+IF(J$2=$E35,$D35,IF(J$2>J$257,0,IF($C35=J$2,"PAGAR"&" "&TEXT($B35," #.##0,00"),0))) -> 0 | K35: =+IF(K$2=$E35,$D35,IF(K$2>K$257,0,IF($C35=K$2,"PAGAR"&" "&TEXT($B35," #.##0,00"),0))) -> 0 | L35: =+IF(L$2=$E35,$D35,IF(L$2>L$257,0,IF($C35=L$2,"PAGAR"&" "&TEXT($B35," #.##0,00"),0))) -> 0 | M35: =+IF(M$2=$E35,$D35,IF(M$2>M$257,0,IF($C35=M$2,"PAGAR"&" "&TEXT($B35," #.##0,00"),0))) -> 0 | N35: =+IF(N$2=$E35,$D35,IF(N$2>N$257,0,IF($C35=N$2,"PAGAR"&" "&TEXT($B35," #.##0,00"),0))) -> 0 | O35: =+IF(O$2=$E35,$D35,IF(O$2>O$257,0,IF($C35=O$2,"PAGAR"&" "&TEXT($B35," #.##0,00"),0))) -> 0 | P35: =+IF(P$2=$E35,$D35,IF(P$2>P$257,0,IF($C35=P$2,"PAGAR"&" "&TEXT($B35," #.##0,00"),0))) -> 0 | Q35: =+IF(Q$2=$E35,$D35,IF(Q$2>Q$257,0,IF($C35=Q$2,"PAGAR"&" "&TEXT($B35," #.##0,00"),0))) -> 0 | ... AM35: =+IF(AM$2=$E35,$D35,IF(AM$2>AM$257,0,IF($C35=AM$2,"PAGAR"&" "&TEXT($B35," #.##0,00"),0))) -> 0 | AN35: =+IF(F35<0,-F35,0) -> 0 | AO35: =+IF(AND(C35=0,B35>0),B35,0) -> 0
A36: Bônus Tamara | B36: 569 | C36: 15 | F36: =+IF(TODAY()<DATEVALUE(1&D$1&E$1),0,IF(C36>0,IF(C36-SUM(I$255:AM$255)<0,B36-SUM(I36:AM36,0),0),0))+IF(C36=-1,B36-SUM(J36:AM36)) -> 0 | G36: =+IF(B36=0,"-",D36/B36) -> 0 | H36: =IF(H$2=$E36,$D36,IF(H$2>H$257,0,IF($C36=H$2,"PAGAR"&" "&TEXT($B36," #.##0,00"),IF($C36=-1,"PAGAR"&" "&TEXT($B36," #.##0,00"),0)))) -> 0 | I36: =IF(I$2=$E36,$D36,IF(I$2>I$257,0,IF($C36=I$2,"PAGAR"&" "&TEXT($B36," #.##0,00"),IF($C36=-1,"PAGAR"&" "&TEXT($B36," #.##0,00"),0)))) -> 0 | J36: =+IF(J$2=$E36,$D36,IF(J$2>J$257,0,IF($C36=J$2,"PAGAR"&" "&TEXT($B36," #.##0,00"),0))) -> 0 | K36: =+IF(K$2=$E36,$D36,IF(K$2>K$257,0,IF($C36=K$2,"PAGAR"&" "&TEXT($B36," #.##0,00"),0))) -> 0 | L36: =+IF(L$2=$E36,$D36,IF(L$2>L$257,0,IF($C36=L$2,"PAGAR"&" "&TEXT($B36," #.##0,00"),0))) -> 0 | M36: =+IF(M$2=$E36,$D36,IF(M$2>M$257,0,IF($C36=M$2,"PAGAR"&" "&TEXT($B36," #.##0,00"),0))) -> 0 | N36: =+IF(N$2=$E36,$D36,IF(N$2>N$257,0,IF($C36=N$2,"PAGAR"&" "&TEXT($B36," #.##0,00"),0))) -> 0 | O36: =+IF(O$2=$E36,$D36,IF(O$2>O$257,0,IF($C36=O$2,"PAGAR"&" "&TEXT($B36," #.##0,00"),0))) -> 0 | P36: =+IF(P$2=$E36,$D36,IF(P$2>P$257,0,IF($C36=P$2,"PAGAR"&" "&TEXT($B36," #.##0,00"),0))) -> 0 | Q36: =+IF(Q$2=$E36,$D36,IF(Q$2>Q$257,0,IF($C36=Q$2,"PAGAR"&" "&TEXT($B36," #.##0,00"),0))) -> 0 | ... AM36: =+IF(AM$2=$E36,$D36,IF(AM$2>AM$257,0,IF($C36=AM$2,"PAGAR"&" "&TEXT($B36," #.##0,00"),0))) -> 0 | AN36: =+IF(F36<0,-F36,0) -> 0 | AO36: =+IF(AND(C36=0,B36>0),B36,0) -> 0
A37: Clayton manutenção | B37: 1000 | C37: 2 | F37: =+IF(TODAY()<DATEVALUE(1&D$1&E$1),0,IF(C37>0,IF(C37-SUM(I$255:AM$255)<0,B37-SUM(I37:AM37,0),0),0))+IF(C37=-1,B37-SUM(J37:AM37)) -> 1000 | G37: =+IF(B37=0,"-",D37/B37) -> 0 | H37: =IF(H$2=$E37,$D37,IF(H$2>H$257,0,IF($C37=H$2,"PAGAR"&" "&TEXT($B37," #.##0,00"),IF($C37=-1,"PAGAR"&" "&TEXT($B37," #.##0,00"),0)))) -> 0 | I37: =IF(I$2=$E37,$D37,IF(I$2>I$257,0,IF($C37=I$2,"PAGAR"&" "&TEXT($B37," #.##0,00"),IF($C37=-1,"PAGAR"&" "&TEXT($B37," #.##0,00"),0)))) -> 0 | J37: =+IF(J$2=$E37,$D37,IF(J$2>J$257,0,IF($C37=J$2,"PAGAR"&" "&TEXT($B37," #.##0,00"),0))) -> PAGAR 1.000,00 | K37: =+IF(K$2=$E37,$D37,IF(K$2>K$257,0,IF($C37=K$2,"PAGAR"&" "&TEXT($B37," #.##0,00"),0))) -> 0 | L37: =+IF(L$2=$E37,$D37,IF(L$2>L$257,0,IF($C37=L$2,"PAGAR"&" "&TEXT($B37," #.##0,00"),0))) -> 0 | M37: =+IF(M$2=$E37,$D37,IF(M$2>M$257,0,IF($C37=M$2,"PAGAR"&" "&TEXT($B37," #.##0,00"),0))) -> 0 | N37: =+IF(N$2=$E37,$D37,IF(N$2>N$257,0,IF($C37=N$2,"PAGAR"&" "&TEXT($B37," #.##0,00"),0))) -> 0 | O37: =+IF(O$2=$E37,$D37,IF(O$2>O$257,0,IF($C37=O$2,"PAGAR"&" "&TEXT($B37," #.##0,00"),0))) -> 0 | P37: =+IF(P$2=$E37,$D37,IF(P$2>P$257,0,IF($C37=P$2,"PAGAR"&" "&TEXT($B37," #.##0,00"),0))) -> 0 | Q37: =+IF(Q$2=$E37,$D37,IF(Q$2>Q$257,0,IF($C37=Q$2,"PAGAR"&" "&TEXT($B37," #.##0,00"),0))) -> 0 | ... AM37: =+IF(AM$2=$E37,$D37,IF(AM$2>AM$257,0,IF($C37=AM$2,"PAGAR"&" "&TEXT($B37," #.##0,00"),0))) -> 0 | AN37: =+IF(F37<0,-F37,0) -> 0 | AO37: =+IF(AND(C37=0,B37>0),B37,0) -> 0 | AQ37: 22 | AS37: 23 | AU37: 24 | AW37: 25 | AY37: 26 | BA37: 27 | BC37: 28
A38: VA 5 anos | B38: 1890 | C38: 3 | F38: =+IF(TODAY()<DATEVALUE(1&D$1&E$1),0,IF(C38>0,IF(C38-SUM(I$255:AM$255)<0,B38-SUM(I38:AM38,0),0),0))+IF(C38=-1,B38-SUM(J38:AM38)) -> 1890 | G38: =+IF(B38=0,"-",D38/B38) -> 0 | H38: =IF(H$2=$E38,$D38,IF(H$2>H$257,0,IF($C38=H$2,"PAGAR"&" "&TEXT($B38," #.##0,00"),IF($C38=-1,"PAGAR"&" "&TEXT($B38," #.##0,00"),0)))) -> 0 | I38: =IF(I$2=$E38,$D38,IF(I$2>I$257,0,IF($C38=I$2,"PAGAR"&" "&TEXT($B38," #.##0,00"),IF($C38=-1,"PAGAR"&" "&TEXT($B38," #.##0,00"),0)))) -> 0 | J38: =+IF(J$2=$E38,$D38,IF(J$2>J$257,0,IF($C38=J$2,"PAGAR"&" "&TEXT($B38," #.##0,00"),0))) -> 0 | K38: =+IF(K$2=$E38,$D38,IF(K$2>K$257,0,IF($C38=K$2,"PAGAR"&" "&TEXT($B38," #.##0,00"),0))) -> PAGAR 1.890,00 | L38: =+IF(L$2=$E38,$D38,IF(L$2>L$257,0,IF($C38=L$2,"PAGAR"&" "&TEXT($B38," #.##0,00"),0))) -> 0 | M38: =+IF(M$2=$E38,$D38,IF(M$2>M$257,0,IF($C38=M$2,"PAGAR"&" "&TEXT($B38," #.##0,00"),0))) -> 0 | N38: =+IF(N$2=$E38,$D38,IF(N$2>N$257,0,IF($C38=N$2,"PAGAR"&" "&TEXT($B38," #.##0,00"),0))) -> 0 | O38: =+IF(O$2=$E38,$D38,IF(O$2>O$257,0,IF($C38=O$2,"PAGAR"&" "&TEXT($B38," #.##0,00"),0))) -> 0 | P38: =+IF(P$2=$E38,$D38,IF(P$2>P$257,0,IF($C38=P$2,"PAGAR"&" "&TEXT($B38," #.##0,00"),0))) -> 0 | Q38: =+IF(Q$2=$E38,$D38,IF(Q$2>Q$257,0,IF($C38=Q$2,"PAGAR"&" "&TEXT($B38," #.##0,00"),0))) -> 0 | ... AM38: =+IF(AM$2=$E38,$D38,IF(AM$2>AM$257,0,IF($C38=AM$2,"PAGAR"&" "&TEXT($B38," #.##0,00"),0))) -> 0 | AN38: =+IF(F38<0,-F38,0) -> 0 | AO38: =+IF(AND(C38=0,B38>0),B38,0) -> 0 | AQ38: {=_xlfn._xlws.FILTER($A$5:$A$152,$C$5:$C$152=AQ37,"livre")} -> Google One IA - Cartão | AR38: {=_xlfn._xlws.FILTER($B$5:$B$152,$C$5:$C$152=AQ37,"livre")} -> 96.99 | AS38: {=_xlfn._xlws.FILTER($A$5:$A$152,$C$5:$C$152=AS37,"livre")} -> Barão Aluguel | AT38: {=_xlfn._xlws.FILTER($B$5:$B$152,$C$5:$C$152=AS37,"livre")} -> 4377.08 | AU38: {=_xlfn._xlws.FILTER($A$5:$A$152,$C$5:$C$152=AU37,"livre")} -> livre | AV38: {=_xlfn._xlws.FILTER($B$5:$B$152,$C$5:$C$152=AU37,"livre")} -> livre | AW38: {=_xlfn._xlws.FILTER($A$5:$A$152,$C$5:$C$152=AW37,"livre")} -> Seguro Vida Presente 21 | AX38: {=_xlfn._xlws.FILTER($B$5:$B$152,$C$5:$C$152=AW37,"livre")} -> 770.07 | AY38: {=_xlfn._xlws.FILTER($A$5:$A$152,$C$5:$C$152=AY37,"livre")} -> Água Barão | AZ38: {=_xlfn._xlws.FILTER($B$5:$B$152,$C$5:$C$152=AY37,"livre")} -> 2775 | BA38: {=_xlfn._xlws.FILTER($A$5:$A$152,$C$5:$C$152=BA37,"livre")} -> IPTU Reserva | BB38: {=_xlfn._xlws.FILTER($B$5:$B$152,$C$5:$C$152=BA37,"livre")} -> 524.07 | BC38: {=_xlfn._xlws.FILTER($A$5:$A$152,$C$5:$C$152=BC37,"livre")} -> Cartão | BD38: {=_xlfn._xlws.FILTER($B$5:$B$152,$C$5:$C$152=BC37,"livre")} -> 1928.17
A39: Lucas VA 5 anos e normal | B39: 420 | C39: 3 | F39: =+IF(TODAY()<DATEVALUE(1&D$1&E$1),0,IF(C39>0,IF(C39-SUM(I$255:AM$255)<0,B39-SUM(I39:AM39,0),0),0))+IF(C39=-1,B39-SUM(J39:AM39)) -> 420 | G39: =+IF(B39=0,"-",D39/B39) -> 0 | H39: =IF(H$2=$E39,$D39,IF(H$2>H$257,0,IF($C39=H$2,"PAGAR"&" "&TEXT($B39," #.##0,00"),IF($C39=-1,"PAGAR"&" "&TEXT($B39," #.##0,00"),0)))) -> 0 | I39: =IF(I$2=$E39,$D39,IF(I$2>I$257,0,IF($C39=I$2,"PAGAR"&" "&TEXT($B39," #.##0,00"),IF($C39=-1,"PAGAR"&" "&TEXT($B39," #.##0,00"),0)))) -> 0 | J39: =+IF(J$2=$E39,$D39,IF(J$2>J$257,0,IF($C39=J$2,"PAGAR"&" "&TEXT($B39," #.##0,00"),0))) -> 0 | K39: =+IF(K$2=$E39,$D39,IF(K$2>K$257,0,IF($C39=K$2,"PAGAR"&" "&TEXT($B39," #.##0,00"),0))) -> PAGAR 420,00 | L39: =+IF(L$2=$E39,$D39,IF(L$2>L$257,0,IF($C39=L$2,"PAGAR"&" "&TEXT($B39," #.##0,00"),0))) -> 0 | M39: =+IF(M$2=$E39,$D39,IF(M$2>M$257,0,IF($C39=M$2,"PAGAR"&" "&TEXT($B39," #.##0,00"),0))) -> 0 | N39: =+IF(N$2=$E39,$D39,IF(N$2>N$257,0,IF($C39=N$2,"PAGAR"&" "&TEXT($B39," #.##0,00"),0))) -> 0 | O39: =+IF(O$2=$E39,$D39,IF(O$2>O$257,0,IF($C39=O$2,"PAGAR"&" "&TEXT($B39," #.##0,00"),0))) -> 0 | P39: =+IF(P$2=$E39,$D39,IF(P$2>P$257,0,IF($C39=P$2,"PAGAR"&" "&TEXT($B39," #.##0,00"),0))) -> 0 | Q39: =+IF(Q$2=$E39,$D39,IF(Q$2>Q$257,0,IF($C39=Q$2,"PAGAR"&" "&TEXT($B39," #.##0,00"),0))) -> 0 | ... AM39: =+IF(AM$2=$E39,$D39,IF(AM$2>AM$257,0,IF($C39=AM$2,"PAGAR"&" "&TEXT($B39," #.##0,00"),0))) -> 0 | AN39: =+IF(F39<0,-F39,0) -> 0 | AO39: =+IF(AND(C39=0,B39>0),B39,0) -> 0 | AQ39: {=_xlfn._xlws.FILTER($A43:$A190,$C43:$C190=1,"livre")} -> Condomínio Sta Rita | AR39: {=_xlfn._xlws.FILTER($B43:$B190,$C43:$C190=1,"livre")} -> 300 | AS39: {=_xlfn._xlws.FILTER($A43:$A190,$C43:$C190=1,"livre")} -> Condomínio Sta Rita | AT39: {=_xlfn._xlws.FILTER($B43:$B190,$C43:$C190=1,"livre")} -> 300 | AW39: Seguro Previdência VGBL 21 | AX39: 675.52 | AY39: Vivo Lago | AZ39: 236.13 | BC39: Yelum Seguro Civic - Cartão | BD39: 286.78
A40: VA normal | B40: 2520 | C40: 28 | F40: =+IF(TODAY()<DATEVALUE(1&D$1&E$1),0,IF(C40>0,IF(C40-SUM(I$255:AM$255)<0,B40-SUM(I40:AM40,0),0),0))+IF(C40=-1,B40-SUM(J40:AM40)) -> 0 | G40: =+IF(B40=0,"-",D40/B40) -> 0 | H40: =IF(H$2=$E40,$D40,IF(H$2>H$257,0,IF($C40=H$2,"PAGAR"&" "&TEXT($B40," #.##0,00"),IF($C40=-1,"PAGAR"&" "&TEXT($B40," #.##0,00"),0)))) -> 0 | I40: =IF(I$2=$E40,$D40,IF(I$2>I$257,0,IF($C40=I$2,"PAGAR"&" "&TEXT($B40," #.##0,00"),IF($C40=-1,"PAGAR"&" "&TEXT($B40," #.##0,00"),0)))) -> 0 | J40: =+IF(J$2=$E40,$D40,IF(J$2>J$257,0,IF($C40=J$2,"PAGAR"&" "&TEXT($B40," #.##0,00"),0))) -> 0 | K40: =+IF(K$2=$E40,$D40,IF(K$2>K$257,0,IF($C40=K$2,"PAGAR"&" "&TEXT($B40," #.##0,00"),0))) -> 0 | L40: =+IF(L$2=$E40,$D40,IF(L$2>L$257,0,IF($C40=L$2,"PAGAR"&" "&TEXT($B40," #.##0,00"),0))) -> 0 | M40: =+IF(M$2=$E40,$D40,IF(M$2>M$257,0,IF($C40=M$2,"PAGAR"&" "&TEXT($B40," #.##0,00"),0))) -> 0 | N40: =+IF(N$2=$E40,$D40,IF(N$2>N$257,0,IF($C40=N$2,"PAGAR"&" "&TEXT($B40," #.##0,00"),0))) -> 0 | O40: =+IF(O$2=$E40,$D40,IF(O$2>O$257,0,IF($C40=O$2,"PAGAR"&" "&TEXT($B40," #.##0,00"),0))) -> 0 | P40: =+IF(P$2=$E40,$D40,IF(P$2>P$257,0,IF($C40=P$2,"PAGAR"&" "&TEXT($B40," #.##0,00"),0))) -> 0 | Q40: =+IF(Q$2=$E40,$D40,IF(Q$2>Q$257,0,IF($C40=Q$2,"PAGAR"&" "&TEXT($B40," #.##0,00"),0))) -> 0 | ... AM40: =+IF(AM$2=$E40,$D40,IF(AM$2>AM$257,0,IF($C40=AM$2,"PAGAR"&" "&TEXT($B40," #.##0,00"),0))) -> 0 | AN40: =+IF(F40<0,-F40,0) -> 0 | AO40: =+IF(AND(C40=0,B40>0),B40,0) -> 0 | AQ40: Letízio mensal | AR40: 1750 | AS40: Letízio mensal | AT40: 1750 | AW40: Contabilidade | AX40: 2211 | AY40: Itaú - débito auto (6/37x) 5% 50k | AZ40: 3099 | BC40: Apple.com - Cartão | BD40: 29.9
...

Sheet PLAN2
D1: =+DESP_JANEIRO!I258 -> 46053 | F1: =DAY(TODAY()) -> 13 | H1: =+DESP_JANEIRO!I256 -> 46023 | I1: =+DESP_JANEIRO!J256 -> 46024 | J1: =+DESP_JANEIRO!K256 -> 46025 | K1: =+DESP_JANEIRO!L256 -> 46026 | L1: =+DESP_JANEIRO!M256 -> 46027 | M1: =+DESP_JANEIRO!N256 -> 46028 | N1: =+DESP_JANEIRO!O256 -> 46029 | O1: =+DESP_JANEIRO!P256 -> 46030 | ... AL1: =+DESP_JANEIRO!AM256 -> 46053
A2: =+DESP_JANEIRO!D1 -> JANEIRO | B2: =+DESP_JANEIRO!E1 -> 2026 | C2: DIAS NO MÊS ==> | D2: =+DESP_JANEIRO!G1 -> 31 | E2: % mês==> | F2: =+SUM(H$172:AL$172)/$D$2 -> 0.41935484 | H2: =IF(H1>$D1,"",WEEKDAY(H1)) -> 5 | I2: =IF(I1>$D1,"",WEEKDAY(I1)) -> 6 | J2: =IF(J1>$D1,"",WEEKDAY(J1)) -> 7 | K2: =IF(K1>$D1,"",WEEKDAY(K1)) -> 1 | L2: =IF(L1>$D1,"",WEEKDAY(L1)) -> 2 | M2: =IF(M1>$D1,"",WEEKDAY(M1)) -> 3 | N2: =IF(N1>$D1,"",WEEKDAY(N1)) -> 4 | O2: =IF(O1>$D1,"",WEEKDAY(O1)) -> 5 | ... AL2: =IF(AL1>$D1,"",WEEKDAY(AL1)) -> 7
A3: DESCRIÇÃO | B3: Orçado | C3: Dia Vencimento | D3: Em atraso | E3: Realizado Acum. | F3: R/O | H3: 1 | I3: =H3+1 -> 2 | J3: =I3+1 -> 3 | K3: =J3+1 -> 4 | L3: =K3+1 -> 5 | M3: =L3+1 -> 6 | N3: =M3+1 -> 7 | O3: =N3+1 -> 8 | P3: =O3+1 -> 9 | ... AL3: =AK3+1 -> 31
D4: e acumulado
A6: =+SUM(H6:AL6)-B6 -> 0 | B6: =+DESP_JANEIRO!B5 -> 6650 | C6: =+DESP_JANEIRO!C5 -> 2 | D6: =+DESP_JANEIRO!F5 -> 0 | E6: =+SUM(H6:AL6) -> 6650 | F6: =+IF(B6=0,"-",E6/B6) -> 1 | H6: =+IF(H$3>$D$2,0,IF(OR(C6=-1,C6=H$3),$B6,0)) -> 0 | I6: =+IF(I$3>$D$2,0,IF($C6=I$3,$B6,0)) -> 6650 | J6: =+IF(J$3>$D$2,0,IF($C6=J$3,$B6,0)) -> 0 | K6: =+IF(K$3>$D$2,0,IF($C6=K$3,$B6,0)) -> 0 | L6: =+IF(L$3>$D$2,0,IF($C6=L$3,$B6,0)) -> 0 | M6: =+IF(M$3>$D$2,0,IF($C6=M$3,$B6,0)) -> 0 | N6: =+IF(N$3>$D$2,0,IF($C6=N$3,$B6,0)) -> 0 | O6: =+IF(O$3>$D$2,0,IF($C6=O$3,$B6,0)) -> 0 | P6: =+IF(P$3>$D$2,0,IF($C6=P$3,$B6,0)) -> 0 | ... AL6: =+IF(AL$3>$D$2,0,IF($C6=AL$3,$B6,0)) -> 0
A7: =+SUM(H7:AL7)-B7 -> 0 | B7: =+DESP_JANEIRO!B6 -> 6359.51 | C7: =+DESP_JANEIRO!C6 -> 7 | D7: =+DESP_JANEIRO!F6 -> 6359.51 | E7: =+SUM(H7:AL7) -> 6359.51 | F7: =+IF(B7=0,"-",E7/B7) -> 1 | H7: =+IF(H$3>$D$2,0,IF(OR(C7=-1,C7=H$3),$B7,0)) -> 0 | I7: =+IF(I$3>$D$2,0,IF($C7=I$3,$B7,0)) -> 0 | J7: =+IF(J$3>$D$2,0,IF($C7=J$3,$B7,0)) -> 0 | K7: =+IF(K$3>$D$2,0,IF($C7=K$3,$B7,0)) -> 0 | L7: =+IF(L$3>$D$2,0,IF($C7=L$3,$B7,0)) -> 0 | M7: =+IF(M$3>$D$2,0,IF($C7=M$3,$B7,0)) -> 0 | N7: =+IF(N$3>$D$2,0,IF($C7=N$3,$B7,0)) -> 6359.51 | O7: =+IF(O$3>$D$2,0,IF($C7=O$3,$B7,0)) -> 0 | P7: =+IF(P$3>$D$2,0,IF($C7=P$3,$B7,0)) -> 0 | ... AL7: =+IF(AL$3>$D$2,0,IF($C7=AL$3,$B7,0)) -> 0
A8: =+SUM(H8:AL8)-B8 -> -770.07 | B8: =+DESP_JANEIRO!B7 -> 770.07 | C8: =+DESP_JANEIRO!C7 -> 0 | D8: =+DESP_JANEIRO!F7 -> 0 | E8: =+SUM(H8:AL8) -> 0 | F8: =+IF(B8=0,"-",E8/B8) -> 0 | H8: =+IF(H$3>$D$2,0,IF(OR(C8=-1,C8=H$3),$B8,0)) -> 0 | I8: =+IF(I$3>$D$2,0,IF($C8=I$3,$B8,0)) -> 0 | J8: =+IF(J$3>$D$2,0,IF($C8=J$3,$B8,0)) -> 0 | K8: =+IF(K$3>$D$2,0,IF($C8=K$3,$B8,0)) -> 0 | L8: =+IF(L$3>$D$2,0,IF($C8=L$3,$B8,0)) -> 0 | M8: =+IF(M$3>$D$2,0,IF($C8=M$3,$B8,0)) -> 0 | N8: =+IF(N$3>$D$2,0,IF($C8=N$3,$B8,0)) -> 0 | O8: =+IF(O$3>$D$2,0,IF($C8=O$3,$B8,0)) -> 0 | P8: =+IF(P$3>$D$2,0,IF($C8=P$3,$B8,0)) -> 0 | ... AL8: =+IF(AL$3>$D$2,0,IF($C8=AL$3,$B8,0)) -> 0
A9: =+SUM(H9:AL9)-B9 -> 0 | B9: =+DESP_JANEIRO!B8 -> 770.07 | C9: =+DESP_JANEIRO!C8 -> 25 | D9: =+DESP_JANEIRO!F8 -> 0 | E9: =+SUM(H9:AL9) -> 770.07 | F9: =+IF(B9=0,"-",E9/B9) -> 1 | H9: =+IF(H$3>$D$2,0,IF(OR(C9=-1,C9=H$3),$B9,0)) -> 0 | I9: =+IF(I$3>$D$2,0,IF($C9=I$3,$B9,0)) -> 0 | J9: =+IF(J$3>$D$2,0,IF($C9=J$3,$B9,0)) -> 0 | K9: =+IF(K$3>$D$2,0,IF($C9=K$3,$B9,0)) -> 0 | L9: =+IF(L$3>$D$2,0,IF($C9=L$3,$B9,0)) -> 0 | M9: =+IF(M$3>$D$2,0,IF($C9=M$3,$B9,0)) -> 0 | N9: =+IF(N$3>$D$2,0,IF($C9=N$3,$B9,0)) -> 0 | O9: =+IF(O$3>$D$2,0,IF($C9=O$3,$B9,0)) -> 0 | P9: =+IF(P$3>$D$2,0,IF($C9=P$3,$B9,0)) -> 0 | ... AL9: =+IF(AL$3>$D$2,0,IF($C9=AL$3,$B9,0)) -> 0
A10: =+SUM(H10:AL10)-B10 -> 0 | B10: =+DESP_JANEIRO!B9 -> 675.52 | C10: =+DESP_JANEIRO!C9 -> 25 | D10: =+DESP_JANEIRO!F9 -> 0 | E10: =+SUM(H10:AL10) -> 675.52 | F10: =+IF(B10=0,"-",E10/B10) -> 1 | H10: =+IF(H$3>$D$2,0,IF(OR(C10=-1,C10=H$3),$B10,0)) -> 0 | I10: =+IF(I$3>$D$2,0,IF($C10=I$3,$B10,0)) -> 0 | J10: =+IF(J$3>$D$2,0,IF($C10=J$3,$B10,0)) -> 0 | K10: =+IF(K$3>$D$2,0,IF($C10=K$3,$B10,0)) -> 0 | L10: =+IF(L$3>$D$2,0,IF($C10=L$3,$B10,0)) -> 0 | M10: =+IF(M$3>$D$2,0,IF($C10=M$3,$B10,0)) -> 0 | N10: =+IF(N$3>$D$2,0,IF($C10=N$3,$B10,0)) -> 0 | O10: =+IF(O$3>$D$2,0,IF($C10=O$3,$B10,0)) -> 0 | P10: =+IF(P$3>$D$2,0,IF($C10=P$3,$B10,0)) -> 0 | ... AL10: =+IF(AL$3>$D$2,0,IF($C10=AL$3,$B10,0)) -> 0
